Workbook
Name _._IMPUESTOS_SOBRE_COMBUSTIBLES_Y_GAS_NATURAL: [1]C!$B$27:$N$27
Name _._IMPUESTOS_SOBRE_ENERGIA_ELECTRICA: [1]C!$B$28:$N$28
Name __r: #REF!
Name __r: #REF!
Name __r: #REF!
Name __r: #REF!
Name __r: #REF!
Name __r: #REF!
Name __r: #REF!
Name __r: #REF!
Name __r: #REF!
Name __r: #REF!
Name __r: #REF!
Name __r: #REF!
Name __r: #REF!
Name __r: #REF!
Name __r: #REF!
Name __r: #REF!
Name __r: #REF!
Name _r: #REF!
Name _r: #REF!
Name _r: #REF!
Name _r: #REF!
Name _r: #REF!
Name _r: #REF!
Name _r: #REF!
Name _r: #REF!
Name _r: #REF!
Name _r: #REF!
Name _r: #REF!
Name _r: #REF!
Name _r: #REF!
Name _r: #REF!
Name _r: #REF!
Name _r: #REF!
Name _r: #REF!
Name A_impresión_IM: '[2]03-08'!#REF!
Name ACC: '[3]CARTERA FONDO'!#REF!
Name ACP: '[3]CARTERA FONDO'!#REF!
Name AMPO5: "Gráfico 8"
Name AÑO: #REF!
Name AÑO: #REF!
Name año2003: #REF!
Name año2003: #REF!
Name cacho: [4]GRAFPROM!#REF!
Name cacho: [4]GRAFPROM!#REF!
Name cacho: [4]GRAFPROM!#REF!
Name carajo: #REF!
Name carajo: #REF!
Name CDF: '[3]CARTERA FONDO'!#REF!
Name CDF: '[3]CARTERA FONDO'!#REF!
Name CFA: '[3]CARTERA FONDO'!#REF!
Name CFD: '[3]CARTERA FONDO'!#REF!
Name CLH: '[3]CARTERA FONDO'!#REF!
Name Coef: [5]CoefStocks!$A$4:$AT$260
Name Coef: [5]CoefStocks!$A$4:$AT$260
Name Coef: [5]CoefStocks!$A$4:$AT$260
Name COPA: #N/A
Name COPARTICIPACION_FEDERAL__LEY_N__23548: [1]C!$B$13:$N$13
Name CUADRO_10.3.1: '[6]fondo promedio'!$A$36:$L$74

Sheet INDICE
B2: MINISTERIO DE ECONOMÍA
B3: SECRETARÍA DE FINANZAS
B5: DEUDA DE LA ADMINISTRACIÓN CENTRAL
B8: ÍNDICE
B10: HOJA | C10: CONTENIDO
B11: Deuda al 31/12/2019: nivel y composición
B12: A.1.1 | C12: Deuda de la Administración Central - Por instrumento y tipo de plazo
B13: A.1.2 | C13: Deuda Bruta de la Administración Central - Por Deuda Directa o Indirecta
B14: A.1.3 | C14: Deuda Bruta de la Administración Central - Por legislación, situación e instrumento
B15: A.1.4 | C15: Deuda Bruta de la Administración Central - Por tipo de moneda y tasa
B16: A.1.5 | C16: Tasa promedio ponderada por moneda e instrumento
B17: A.1.6 | C17: Vida promedio por instrumento
B18: A.1.7 | C18: Títulos públicos y letras del tesoro emitidos en moneda nacional
B19: A.1.8 | C19: Títulos públicos, letras del tesoro, pagarés y préstamos garantizados emitidos en moneda nacional y ajustables por CER
B20: A.1.9 | C20: Títulos públicos, letras del tesoro y pagarés emitidos en moneda extranjera
B21: A.1.10 | C21: Deuda elegible pendiente de reestructuración, desagregada por instrumento
B23: Evolución reciente de la deuda
B24: A.2.1 | C24: Deuda Bruta de la Administración Central - Serie de saldos trimestrales - 4to. Trimestre 2018/4to. Trimestre 2019
B25: A.2.2 | C25: Deuda Bruta de la Administración Central - Flujos y variaciones 4to. Trimestre 2019
B26: A.2.3 | C26: Deuda Bruta de la Administración Central - Flujos y variaciones acumulados 2019
B27: A.2.4 | C27: Serie de Tipos de Cambio y Coeficiente de Estabilización de Referencia (CER)
B28: A.2.5 | C28: Serie de la Deuda del Sector Público Nacional por año - 1992/2019
B30: Vencimientos de capital e interés de la deuda al 31-12-2019 proyectados
B31: A.3.1 | C31: Perfil mensual de vencimientos de capital e interés de la Deuda Bruta de la Administración Central - 01/2020 a 12/2020
B32: A.3.2 | C32: Perfil mensual de vencimientos de capital de la Deuda Bruta de la Administración Central, desagregado por instrumento - 2020
B33: A.3.3 | C33: Perfil mensual de vencimientos de interés de la Deuda Bruta de la Administración Central, desagregado por instrumento - 2020
B34: A.3.4 | C34: Perfil mensual de vencimientos de capital de la Deuda Bruta de la Administración Central, desagregado por instrumento - 2021
B35: A.3.5 | C35: Perfil mensual de vencimientos de interés de la Deuda Bruta de la Administración Central, desagregado por instrumento - 2021
B36: A.3.6 | C36: Perfil anual de vencimientos de capital e interés de la Deuda Bruta de la Administración Central
B37: A.3.7 | C37: Perfil anual de vencimientos de capital de la Deuda Bruta de la Administración Central, desagregado por instrumento
B38: A.3.8 | C38: Perfil anual de vencimientos de interés de la Deuda Bruta de la Administración Central, desagregado por instrumento
B40: Otros Cuadros
B41: A.4.1 | C41: Valores Negociables Vinculados al PBI
B42: A.4.2 | C42: Activos financieros de la Administración Central
B43: A.4.3 | C43: Activos financieros con cargo a provincias
B44: A.4.4 | C44: Flujos netos anuales con Organismos Internacionales
B45: A.4.5 | C45: Deuda Bruta de la Administración Central - Por residencia del tenedor
B46: A.4.6 | C46: Deuda Bruta Externa de la Administración Central - Perfil de vencimientos de capital
B47: A.4.7 | C47: Indicadores de sostenibilidad de la Deuda Bruta de la Administración Central

Sheet A.1.1
A1: Indice
B2: =+INDICE!B2 -> MINISTERIO DE ECONOMÍA
B3: SECRETARÍA DE FINANZAS
B6: DEUDA DE LA ADMINISTRACIÓN CENTRAL
B7: POR INSTRUMENTO Y POR TIPO DE PLAZO
B10: Datos al 31/12/2019
C11: Miles de u$s | D11: Miles de $
B13: I- DEUDA BRUTA + VALORES NEGOCIABLES VINCULADOS AL PBI (II + VI) | C13: =+C16+C84 -> 3.3602735e+08 | D13: =+D16+D84 -> 2.0126358e+10
B16: II- DEUDA BRUTA (III + IV + V) | C16: =+C19+C61+C66 -> 3.2306462e+08 | D16: =+D19+D61+D66 -> 1.9349955e+10
B19: III- DEUDA EN SITUACIÓN DE PAGO NORMAL | C19: =+C21+C54 -> 3.2052545e+08 | D19: =+D21+D54 -> 1.9197872e+10
B21: MEDIANO Y LARGO PLAZO | C21: =+C23+C27+C29+C52 -> 3.0116072e+08 | D21: =+D23+D27+D29+D52 -> 1.8038022e+10
B23: TÍTULOS PÚBLICOS | C23: =+C24+C25 -> 1.9415281e+08 | D23: =+D24+D25 -> 1.1628783e+10
B24: - Moneda nacional | C24: 38723467 | D24: 2.3193421e+09
B25: - Moneda extranjera | C25: 1.5542934e+08 | D25: 9.3094405e+09
B27: LETRAS DEL TESORO (1) | C27: 23113729 | D27: 1.3843968e+09
B29: PRÉSTAMOS | C29: =+C31+C33+C44+C46+C48+C50 -> 79052379 | D29: =+D31+D33+D44+D46+D48+D50 -> 4.7348422e+09
B31: PRÉSTAMOS GARANTIZADOS | C31: 640325.05 | D31: 38352269
B33: ORGANISMOS INTERNACIONALES | C33: =SUM(C34:C42) -> 68000788 | D33: =SUM(D34:D42) -> 4.0729072e+09
B34: - BCIE | C34: 2625 | D34: 157224.38
B35: - BIRF | C35: 7127849.6 | D35: 4.2692255e+08
B36: - BID | C36: 12646999 | D36: 7.5749198e+08
B37: - FONPLATA | C37: 237350.83 | D37: 14216128
B38: - FIDA | C38: 41144.733 | D38: 2464363.8
B39: - CAF | C39: 3655847.8 | D39: 2.1896701e+08
B40: - OFID | C40: 74644.737 | D40: 4470846.5
B41: - FMI | C41: 44128471 | D41: 2.6430748e+09
B42: - BEI | C42: 85856.372 | D42: 5142367.4
B44: ORGANISMOS OFICIALES | C44: 5398072.3 | D44: 3.2331754e+08
B46: BANCA COMERCIAL | C46: =2784897.19483012-C59 -> 2284020.7 | D46: =166801417.48435-D59 -> 1.3680142e+08
B48: AVALES | C48: 2396978.6 | D48: 1.4356703e+08
B50: PAGARÉS DEL TESORO | C50: 332193.96 | D50: 19896757
B52: ADELANTOS TRANSITORIOS BCRA | C52: 4841806.5 | D52: 290000000
B54: CORTO PLAZO (2) | C54: =SUM(C55:C60) -> 19364729 | D54: =SUM(D55:D60) -> 1.1598504e+09
B56: ADELANTOS TRANSITORIOS BCRA | C56: 9395275.1 | D56: 562730000
B57: LETRAS DEL TESORO | C57: 8177985.1 | D57: 4.8982042e+08
B58: PAGARÉS DEL TESORO | C58: 1290591.9 | D58: 77300000
B59: BANCA COMERCIAL | C59: 500876.53 | D59: 30000000
B61: IV- DEUDA EN SITUACIÓN DE PAGO DIFERIDO | C61: =+C63+C64 -> 103955.23 | D61: =+D63+D64 -> 6226398.8
B63: CAPITAL | C63: 95681.181 | D63: 5730824.4
B64: INTERÉS | C64: 8274.0532 | D64: 495574.42
...

Sheet A.1.2
A1: Indice
B2: =+INDICE!B2 -> MINISTERIO DE ECONOMÍA
B3: SECRETARÍA DE FINANZAS
B6: DEUDA BRUTA DE LA ADMINISTRACIÓN CENTRAL
B7: POR DEUDA DIRECTA E INDIRECTA
B10: Datos al 31/12/2019
C11: Miles de u$s
B13: I- DEUDA BRUTA (II + III) | C13: =+C16+C47 -> 3.2306462e+08
B16: II- DEUDA DIRECTA | C16: =+C18+C29+C36+C41 -> 3.1176384e+08
B18: LARGO PLAZO | C18: =SUM(C20:C27) -> 2.8985995e+08
B20: Títulos Públicos | C20: 1.9415281e+08
B21: Préstamos Garantizados | C21: 640325.05
B22: Organismos Intenacionales | C22: 66549766
B23: Organismos Oficiales | C23: 5350516.8
B24: Banca Comercial | C24: 2247237.7
B25: Adelantos Transitorios | C25: 4841806.5
B26: Letras del Tesoro | C26: 15745290
B27: Pagarés del Tesoro | C27: 332193.96
B29: CORTO PLAZO (1) | C29: =SUM(C31:C35) -> 19364729
B31: Adelantos Transitorios | C31: 9395275.1
B32: Letras del Tesoro | C32: 8177985.1
B33: Pagarés del Tesoro | C33: 1290591.9
B34: Banca Comercial | C34: 500876.53
B36: DEUDA EN SITUACIÓN DE PAGO DIFERIDO | C36: =+C38+C39 -> 103955.23
B38: Capital | C38: 95681.181
B39: Interés (2) | C39: 8274.0532
B41: DEUDA ELEGIBLE PENDIENTE DE REESTRUCTURACIÓN (3) | C41: =+C43+C44+C45 -> 2435209.5
B43: Capital | C43: 1058079.7
B44: Atrasos de Interés | C44: 863857.57
B45: Intereses compensatorios (4) | C45: 513272.22
B47: III- DEUDA INDIRECTA | C47: =+C49 -> 11300779
B49: DEUDA A VENCER | C49: =SUM(C51:C53) -> 11300779
B51: Avales | C51: 2396978.6
B52: Garantías a las provincias | C52: 1535361.3
B53: Letras en garantía | C53: 7368439.5
B56: (1) Incluye operaciones de hasta un año de plazo.
B57: (2) No incluye intereses moratorios ni punitorios.
B58: (3) Se trata de la deuda elegible y no presentada al canje (Dtos. 1735/04 y 563/10) y no cancelada a la fecha en el marco de los acuerdos contemplados en la Ley n° 27.249.
B59: (4) Intereses compensatorios estimados, devengados e impagos con posterioridad a la fecha de vencimiento de cada título.

Sheet A.1.3
A1: Indice
B2: =+INDICE!B2 -> MINISTERIO DE ECONOMÍA
B3: SECRETARÍA DE FINANZAS
B6: DEUDA BRUTA DE LA ADMINISTRACIÓN CENTRAL
B7: POR LEGISLACIÓN, INSTRUMENTO Y SITUACIÓN
B10: Datos al 31/12/2019
C11: Saldo Bruto | D11: %
C12: Miles de u$s
B14: DEUDA BRUTA + VALORES NEGOCIABLES VINCULADOS AL PBI | C14: =+C17+C64 -> 3.3602735e+08
B17: - DEUDA BRUTA | C17: =+C19+C21+C23 -> 3.2306462e+08 | D17: =+D19+D21+D23 -> 1
B19: - EN SITUACIÓN DE PAGO NORMAL | C19: =+C28+C47 -> 3.2052545e+08 | D19: =+C19/$C$17 -> 0.99214038
B21: - EN SITUACIÓN DE PAGO DIFERIDO | C21: =+C36+C54 -> 103955.23 | D21: =+C21/$C$17 -> 0.00032177846
B23: - ELEGIBLE PENDIENTE DE REESTRUCTURACIÓN (1) | C23: =+C40+C58 -> 2435209.5 | D23: =+C23/$C$17 -> 0.0075378404
B26: I- LEGISLACIÓN ARGENTINA | C26: =+C28+C36+C40 -> 1.8047064e+08 | D26: =+D28+D36+D40 -> 0.55862088
B28: - EN SITUACIÓN DE PAGO NORMAL | C28: =SUM(C29:C34) -> 1.8034445e+08 | D28: =+C28/$C$17 -> 0.55823026
B29: TÍTULOS PÚBLICOS Y LETRAS DEL TESORO | C29: 1.5894188e+08 | D29: =+C29/$C$17 -> 0.4919817
B30: PRÉSTAMOS GARANTIZADOS | C30: 640325.05 | D30: =+C30/$C$17 -> 0.001982034
B31: ANTICIPO - BCRA | C31: 14237082 | D31: =+C31/$C$17 -> 0.044068836
B32: AVALES | C32: 2396978.6 | D32: =+C32/$C$17 -> 0.007419502
B33: BANCA | C33: 2505397.8 | D33: =+C33/$C$17 -> 0.007755098
B34: PAGÁRES | C34: 1622785.8 | D34: =+C34/$C$17 -> 0.0050230998
B36: - EN SITUACIÓN DE PAGO DIFERIDO | C36: =+C37+C38 -> 62140.321 | D36: =+C36/$C$17 -> 0.00019234642
B37: BANCA | C37: 60760.484 | D37: =+C37/$C$17 -> 0.00018807533
B38: OTROS | C38: 1379.8369 | D38: =+C38/$C$17 -> 4.2710863e-06
B40: - ELEGIBLE PENDIENTE DE REESTRUCTURACIÓN (1) | C40: =SUM(C41:C43) -> 64053.987 | D40: =+C40/$C$17 -> 0.00019826989
B41: CAPITAL | C41: 51462.785 | D41: =+C41/$C$17 -> 0.00015929564
B42: ATRASOS DE INTERÉS | C42: 2780.9178 | D42: =+C42/$C$17 -> 8.6079306e-06
B43: INTERESES COMPENSATORIOS (2) | C43: 9810.2835 | D43: =+C43/$C$17 -> 3.036632e-05
B45: II- LEGISLACIÓN EXTRANJERA | C45: =+C47+C54+C58 -> 1.4259398e+08 | D45: =+D47+D54+D58 -> 0.44137912
B47: - EN SITUACIÓN DE PAGO NORMAL | C47: =SUM(C48:C52) -> 1.4018101e+08 | D47: =+C47/$C$17 -> 0.43391012
B48: TÍTULOS PÚBLICOS Y LETRAS DEL TESORO | C48: 66502646 | D48: =+C48/$C$17 -> 0.20584936
B49: ORGANISMOS INTERNACIONALES | C49: 68000788 | D49: =+C49/$C$17 -> 0.21048665
B50: AVALES | C50: 0 | D50: =+C50/$C$17 -> 0
B51: BILATERALES | C51: 5398072.3 | D51: =+C51/$C$17 -> 0.016708955
B52: BANCA | C52: 279499.42 | D52: =+C52/$C$17 -> 0.0008651502
B54: - EN SITUACIÓN DE PAGO DIFERIDO | C54: =SUM(C55:C56) -> 41814.913 | D54: =+C54/$C$17 -> 0.00012943204
B55: BANCA | C55: 33130.081 | D55: =+C55/$C$17 -> 0.00010254939
B56: OTROS | C56: 8684.8323 | D56: =+C56/$C$17 -> 2.6882647e-05
B58: - ELEGIBLE PENDIENTE DE REESTRUCTURACIÓN (1) | C58: =SUM(C59:C61) -> 2371155.5 | D58: =+C58/$C$17 -> 0.0073395705
B59: CAPITAL | C59: 1006617 | D59: =+C59/$C$17 -> 0.0031158378
...

Sheet A.1.4
A1: Indice
B2: =+INDICE!B2 -> MINISTERIO DE ECONOMÍA
B3: SECRETARÍA DE FINANZAS
B6: DEUDA BRUTA DE LA ADMINISTRACIÓN CENTRAL
B7: POR MONEDA Y TASA
C10: AL 31/12/2019
C11: Deuda Bruta de la Administración Central (Excluida la elegible pendiente de reestructuración) | E11: Deuda elegible pendiente de reestructuración | G11: Total Deuda Bruta
C13: Miles de u$s | D13: % | E13: Miles de u$s | F13: % | G13: Miles de u$s | H13: %
B15: TOTAL | C15: =+C17+C28 -> 3.2062941e+08 | D15: =+D17+D28 -> 0.99246216 | E15: =+E17+E28 -> 2435209.5 | F15: =+F17+F28 -> 0.0075378404 | G15: =+G17+G28 -> 3.2306462e+08 | H15: =+H17+H28 -> 1
B17: Moneda local (1) | C17: =+C19+C24 -> 71582514 | D17: =+D19+D24 -> 0.22157336 | E17: =+E19+E24 -> 63183.869 | F17: =+F19+F24 -> 0.00019557657 | G17: =+G19+G24 -> 71645698 | H17: =+H19+H24 -> 0.22176894
B19: Deuda no ajustable por CER | C19: =SUM(C20:C22) -> 47129925 | D19: =SUM(D20:D22) -> 0.1458839 | E19: =SUM(E20:E22) -> 528.18495 | F19: =SUM(F20:F22) -> 1.6349204e-06 | G19: =SUM(G20:G22) -> 47130454 | H19: =SUM(H20:H22) -> 0.14588553
B20: Tasa fija | C20: 18925634 | D20: =+C20/$G$15 -> 0.058581575 | E20: 15.065927 | F20: =+E20/$G$15 -> 4.6634406e-08 | G20: =+C20+E20 -> 18925649 | H20: =+F20+D20 -> 0.058581622
B21: Tasa Cero | C21: 19378713 | D21: =+C21/$G$15 -> 0.059984016 | E21: 0 | F21: =+E21/$G$15 -> 0 | G21: =+C21+E21 -> 19378713 | H21: =+F21+D21 -> 0.059984016
B22: Tasas Variables | C22: 8825578.1 | D22: =+C22/$G$15 -> 0.027318306 | E22: 513.11902 | F22: =+E22/$G$15 -> 1.588286e-06 | G22: =+C22+E22 -> 8826091.2 | H22: =+F22+D22 -> 0.027319894
B24: Deuda ajustable por CER | C24: =SUM(C25:C26) -> 24452589 | D24: =SUM(D25:D26) -> 0.075689467 | E24: =SUM(E25:E26) -> 62655.684 | F24: =SUM(F25:F26) -> 0.00019394165 | G24: =SUM(G25:G26) -> 24515244 | H24: =SUM(H25:H26) -> 0.075883408
B25: Tasa fija | C25: 23719447 | D25: =+C25/$G$15 -> 0.073420131 | E25: 54181.903 | F25: =+E25/$G$15 -> 0.00016771228 | G25: =+C25+E25 -> 23773629 | H25: =+F25+D25 -> 0.073587844
B26: Tasa cero | C26: 733141.89 | D26: =+C26/$G$15 -> 0.0022693351 | E26: 8473.7817 | F26: =+E26/$G$15 -> 2.6229371e-05 | G26: =+C26+E26 -> 741615.67 | H26: =+F26+D26 -> 0.0022955645
B28: Moneda extranjera | C28: =+C30+C37+C47+C50+C44 -> 2.4904689e+08 | D28: =+D30+D37+D47+D50+D44 -> 0.7708888 | E28: =+E30+E37+E47+E50+E44 -> 2372025.7 | F28: =+F30+F37+F47+F50+F44 -> 0.0073422638 | G28: =+G30+G37+G47+G50+G44 -> 2.5141892e+08 | H28: =+H30+H37+H47+H50+H44 -> 0.77823106
B30: Deuda en dólares estadounidenses | C30: =SUM(C31:C33) -> 1.8263308e+08 | D30: =SUM(D31:D33) -> 0.5653144 | E30: =SUM(E31:E33) -> 1467619.6 | F30: =SUM(F31:F33) -> 0.004542805 | G30: =SUM(G31:G33) -> 1.841007e+08 | H30: =SUM(H31:H33) -> 0.56985721
B31: Tasa fija | C31: 94167632 | D31: =+C31/$G$15 -> 0.29148234 | E31: 1379688.2 | F31: =+E31/$G$15 -> 0.004270626 | G31: =+C31+E31 -> 95547320 | H31: =+F31+D31 -> 0.29575297
B32: Tasa Cero | C32: 19561887 | D32: =+C32/$G$15 -> 0.060551004 | E32: 63 | F32: =+E32/$G$15 -> 1.9500743e-07 | G32: =+C32+E32 -> 19561950 | H32: =+F32+D32 -> 0.060551199
B33: Tasas Variables | C33: =+C34+C35 -> 68903563 | D33: =+D34+D35 -> 0.21328106 | E33: =+E34+E35 -> 87868.416 | F33: =+F34+F35 -> 0.00027198403 | G33: =+C33+E33 -> 68991432 | H33: =+H34+H35 -> 0.21355304
B34: Tasa Libo | C34: 18185903 | D34: =+C34/$G$15 -> 0.056291844 | E34: 80677.426 | F34: =+E34/$G$15 -> 0.00024972535 | G34: =+C34+E34 -> 18266581 | H34: =+F34+D34 -> 0.05654157
B35: Otras tasas variables | C35: 50717660 | D35: =+C35/$G$15 -> 0.15698921 | E35: 7190.9894 | F35: =+E35/$G$15 -> 2.2258672e-05 | G35: =+C35+E35 -> 50724851 | H35: =+F35+D35 -> 0.15701147
B37: Deuda en Euros | C37: =SUM(C38:C40) -> 20923263 | D37: =SUM(D38:D40) -> 0.064764946 | E37: =SUM(E38:E40) -> 856021.6 | F37: =SUM(F38:F40) -> 0.0026496916 | G37: =SUM(G38:G40) -> 21779284 | H37: =SUM(H38:H40) -> 0.067414638
B38: Tasa fija | C38: 20613223 | D38: =+C38/$G$15 -> 0.063805265 | E38: 840951.34 | F38: =+E38/$G$15 -> 0.0026030438 | G38: =+C38+E38 -> 21454175 | H38: =+F38+D38 -> 0.066408308
B39: Tasa Cero | C39: 16814.258 | D39: =+C39/$G$15 -> 5.2046116e-05 | E39: 0 | F39: =+E39/$G$15 -> 0 | G39: =+C39+E39 -> 16814.258 | H39: =+F39+D39 -> 5.2046116e-05
B40: Tasas Variables | C40: =SUM(C41:C42) -> 293224.94 | D40: =+D41+D42 -> 0.00090763558 | E40: =+E41+E42 -> 15070.258 | F40: =+F41+F42 -> 4.6647813e-05 | G40: =+C40+E40 -> 308295.2 | H40: =+H41+H42 -> 0.00095428339
B41: Tasa Libo | C41: 283373.18 | D41: =+C41/$G$15 -> 0.00087714086 | E41: 7516.1818 | F41: =+E41/$G$15 -> 2.3265258e-05 | G41: =+C41+E41 -> 290889.36 | H41: =+F41+D41 -> 0.00090040612
B42: Otras tasas variables | C42: 9851.7637 | D42: =+C42/$G$15 -> 3.0494716e-05 | E42: 7554.076 | F42: =+E42/$G$15 -> 2.3382554e-05 | G42: =+C42+E42 -> 17405.84 | H42: =+F42+D42 -> 5.387727e-05
B44: Deuda en Derechos especiales de giro | C44: =+C45 -> 44141598 | D44: =+SUM(D45:D46) -> 0.13663396 | E44: =+SUM(E45:E46) -> 0 | F44: =+SUM(F45:F46) -> 0 | G44: =+SUM(G45:G46) -> 44141598 | H44: =+SUM(H45:H46) -> 0.13663396
B45: Tasa Variable | C45: 44141598 | D45: =+C45/$G$15 -> 0.13663396 | E45: 0 | F45: =+E45/$G$15 -> 0 | G45: =+C45+E45 -> 44141598 | H45: =+F45+D45 -> 0.13663396
B47: Deuda en Yenes | C47: =+SUM(C48:C48) -> 760001.93 | D47: =+SUM(D48:D48) -> 0.0023524765 | E47: =+SUM(E48:E48) -> 29507.264 | F47: =+SUM(F48:F48) -> 9.1335486e-05 | G47: =+SUM(G48:G48) -> 789509.19 | H47: =+SUM(H48:H48) -> 0.002443812
B48: Tasa fija | C48: 760001.93 | D48: =+C48/$G$15 -> 0.0023524765 | E48: 29507.264 | F48: =+E48/$G$15 -> 9.1335486e-05 | G48: =+C48+E48 -> 789509.19 | H48: =+F48+D48 -> 0.002443812
B50: Deuda en otras monedas extranjeras (2) | C50: =SUM(C51:C51) -> 588950.07 | D50: =SUM(D51:D51) -> 0.0018230101 | E50: =SUM(E51:E51) -> 18877.219 | F50: =SUM(F51:F51) -> 5.8431712e-05 | G50: =SUM(G51:G51) -> 607827.28 | H50: =SUM(H51:H51) -> 0.0018814418
B51: Tasa fija | C51: 588950.07 | D51: =+C51/$G$15 -> 0.0018230101 | E51: 18877.219 | F51: =+E51/$G$15 -> 5.8431712e-05 | G51: =+C51+E51 -> 607827.28 | H51: =+F51+D51 -> 0.0018814418
B54: (1) La deuda emitida en dólares, pero cuyo pago de capital e interés es en pesos, se clasifica como deuda en Moneda Local.
B55: (2) Incluye: Libras esterlinas, Franco Suizo, Corona Danesa, Corona Sueca, Dólar Canadiense, Dinar Kuwaiti, Dólar Australiano y Dirham de Emiratos Árabes Unidos.

Sheet A.1.5
A1: Indice
B2: =+INDICE!B2 -> MINISTERIO DE ECONOMÍA
B3: SECRETARÍA DE FINANZAS
B6: TASA PROMEDIO PONDERADA (1)
B7: POR MONEDA E INSTRUMENTO
B10: Datos al 31/12/2019
B11: TASA PROMEDIO PONDERADA TOTAL | C11: 0.0683702
B13: Deuda en pesos no ajustables por CER | C13: 0.22375586
B15: Títulos Públicos | C15: 0.31316824
B16: Letras del Tesoro | C16: 0.46124717
B17: Otros préstamos | C17: 0.088454462
B18: Adelantos Transitorios BCRA | C18: 0
B20: Deuda en pesos ajustables por CER | C20: 0.037025269
B22: Títulos Públicos | C22: 0.035037518
B23: Letras del Tesoro | C23: 0.092720316
B24: Préstamos garantizados | C24: 0.05
B25: Otros préstamos | C25: 0.0177
B27: Deuda en dólares estadounidenses | C27: 0.04449113
... B56: Otros préstamos | C56: 0.069
B59: (1) Nota Metodológica: Cálculo realizado sobre la deuda en situación de pago normal. Se aplican las tasas de referencia vigentes al 31/12/2019, incluyendo la tasa "plena" en aquellos instrumentos que capitalizan parte de los intereses que devengan.

Sheet A.1.6
A1: Indice
B2: =+INDICE!B2 -> MINISTERIO DE ECONOMÍA
B3: =+A.1.5!B3 -> SECRETARÍA DE FINANZAS
B6: VIDA PROMEDIO (1)
B7: POR INSTRUMENTO
B10: Datos al 31/12/2019 | C10: - En años -
B12: VIDA PROMEDIO TOTAL | C12: 6.9359943
B14: Títulos Públicos | C14: 8.6644495
B16: Letras en Garantía | C16: 10.828226
B18: Letras del Tesoro | C18: 1.0911559
B20: Total Préstamos | C20: 5.1452953
B22: - Organismos Internacionales | C22: 5.4973516
B24: - Organismos Oficiales | C24: 4.1665155
B26: - Préstamos Garantizados (Canje Noviembre 2001) | C26: 10.868862
B28: - Pagarés del Tesoro | C28: 3.7027543
B30: - Banca Comercial | C30: 1.3549629
B32: - Avales | C32: 1.2133014
B34: Adelantos Transitorios | C34: 1.3400842
B37: (1) Nota Metodológica: Cálculo realizado sobre la deuda en situación de pago normal.

Sheet A.1.7
A1: Indice
B2: =+INDICE!B2 -> MINISTERIO DE ECONOMÍA
B3: SECRETARÍA DE FINANZAS
B6: TÍTULOS PÚBLICOS Y LETRAS DEL TESORO
B7: EMITIDOS EN MONEDA NACIONAL
B8: DATOS AL 31/12/2019
H11: En miles de u$s
B12: Fecha de emisión | C12: Denominación | D12: Tasa vigente | E12: Vencimiento | F12: Valor nominal original en circulación | G12: Valor nominal residual en circulación (1) | H12: Valor nominal actualizado en circulación (2)
L14: =+K14-J14 -> 0
C18: TÍTULOS PÚBLICOS | F18: =+F20+F23+F39 -> 16203519 | G18: =+G20+G23+G39 -> 15483558 | H18: =+H20+H23+H39 -> 15960048
C20: BONOS DE CONSOLIDACIÓN | F20: =+F21 -> 90051.553 | G20: =+G21 -> 81046.398 | H20: =+H21 -> 142211.47
B21: 40182 | C21: PR15/$/BADLAR/04-10-2022 | D21: Badlar Bancos Privados | E21: 2022 | F21: 90051.553 | G21: 81046.398 | H21: 142211.47
C23: BONOS | F23: =SUM(F24:F37) -> 16113468 | G23: =SUM(G24:G37) -> 15402511 | H23: =SUM(H24:H37) -> 15817834
B24: 43294 | C24: BONAR/DLK/4,50% U$S/13-02-2020 (3) | D24: 0.045 | E24: 2020 | F24: 1637771.5 | G24: 1637771.5 | H24: 1637771.5
B25: 43193 | C25: BONAR/$/6,72763943919512%/31-12-2028 | D25: 0.067276394 | E25: 2028 | F25: 782776.57 | G25: 705558.06 | H25: 705558.06
B26: 42828 | C26: BONAR/$/BADLAR+200PB/03-04-2022 | D26: Badlar Bancos Privados + 2,00% | E26: 2022 | F26: 895319.19 | G26: 895319.19 | H26: 895319.19
B27: 41631 | C27: BONAR/$/BADLAR+300PB/23-12-2020 | D27: Badlar Bancos Privados + 3,00% | E27: 2020 | F27: 591447.28 | G27: 591447.28 | H27: 591447.28
B28: 42430 | C28: BONAR/$/BADLAR+325PB/01-03-2020 | D28: Badlar Bancos Privados + 3,25% | E28: 2020 | F28: 279281.88 | G28: 279281.88 | H28: 279281.88
B29: 32875 | C29: BONO CONSOLIDADO/$/02-01-2089 | D29: Tasa Cero | E29: 2089 | F29: 14716.816 | G29: 13245.134 | H29: 13245.134
B30: 43272 | C30: BONTE/$/26,00%/21-11-2020 | D30: 0.26 | E30: 2020 | F30: 2083791 | G30: 2083791 | H30: 2083791
B31: 42660 | C31: BONTE/$/15,50%/17-10-2026 | D31: 0.155 | E31: 2026 | F31: 1612316.8 | G31: 1612316.8 | H31: 1612316.8
B32: 42660 | C32: BONTE/$/16,00%/17-10-2023 | D32: 0.16 | E32: 2023 | F32: 1071046.9 | G32: 1071046.9 | H32: 1071046.9
B33: 43172 | C33: BONTE/$/17,25%/13-09-2021 | D33: 0.1725 | E33: 2021 | F33: 1474292.1 | G33: 1474292.1 | H33: 1889614.9
B34: 42646 | C34: BONTE/$/18,20%/03-10-2021 | D34: 0.182 | E34: 2021 | F34: 1043492.8 | G34: 1043492.8 | H34: 1043492.8
B35: 42907 | C35: BOTAPO/$/TPE/21-06-2020 | D35: Tasa Política Económica | E35: 2020 | F35: 2377131.9 | G35: 2377131.9 | H35: 2377131.9
B36: 43504 | C36: BONAR/$/BADLAR+200/08-02-2021 | D36: Badlar Bancos Privados + 2,00% | E36: 2021 | F36: 667835.38 | G36: 667835.38 | H36: 667835.38
B37: 43523 | C37: BONOS PGN 2021/DLK/28-06-2021 | D37: Tasa Cero | E37: 2021 | F37: 1582247.6 | G37: 949981.47 | H37: 949981.47
C39: AMPAROS Y EXCEPCIONES | H39: 2.5156491
C41: LETRAS DEL TESORO | F41: =+SUM(F43:F71) -> 11988755 | G41: =+SUM(G43:G71) -> 10388789 | H41: =+SUM(H43:H71) -> 12363889
B43: 43362 | C43: LETRA/DLK/CMEA/21-09-2020 | D43: Tasa Cero | E43: 2020 | F43: 185335.3 | G43: 185335.3 | H43: 185335.3
B44: 43668 | C44: LETRA/$/FFSIT/20-01-2020 | D44: Tasa Badlar Pública | E44: 2020 | F44: 16695.884 | G44: 16695.884 | H44: 16695.884
B45: 43691 | C45: LETRA/$/FFSIT/12-02-2020 | D45: Tasa Badlar Pública | E45: 2020 | F45: 20869.856 | G45: 20869.856 | H45: 20869.856
B46: 43724 | C46: LETRA/$/FFSIT/16-03-2020 | D46: Tasa Badlar Pública | E46: 2020 | F46: 68620.085 | G46: 68620.085 | H46: 68620.085
B47: 43822 | C47: LETES/$/BADLAR+300PB/22-06-20 | D47: Badlar Bancos Privados + 3,00% | E47: 2020 | F47: 410862.96 | G47: 410862.96 | H47: 410862.96
B48: 43829 | C48: LETES/$/BADLAR+200PB/03-04-20 | D48: Badlar Bancos Privados + 2,00% | E48: 2020 | F48: 207145.79 | G48: 207145.79 | H48: 207145.79
B49: 43721 | C49: LETRA/$/FGS/13-03-2020 | D49: Tasa Badlar Pública + 5,00% | E49: 2020 | F49: 584355.96 | G49: 584355.96 | H49: 584355.96
B50: 43745 | C50: LETRA/$/FGS/01-04-2020 | D50: Tasa Badlar Pública + 5,00% | E50: 2020 | F50: 200350.61 | G50: 200350.61 | H50: 200350.61
B51: 43760 | C51: LETRA/$/FGS/17-04-2020 | D51: Tasa Badlar Pública + 5,00% | E51: 2020 | F51: 33391.769 | G51: 33391.769 | H51: 33391.769
B52: 43773 | C52: LETRA/$/FGS/30-04-2020 | D52: Tasa Badlar Pública + 5,00% | E52: 2020 | F52: 66783.538 | G52: 66783.538 | H52: 66783.538
B53: 43798 | C53: LETRA/$/FGS/27-05-2020 | D53: Tasa Badlar Pública + 5,00% | E53: 2020 | F53: 83479.422 | G53: 83479.422 | H53: 83479.422
...

Sheet A.1.8
A1: Indice
B2: =+INDICE!B2 -> MINISTERIO DE ECONOMÍA
B3: SECRETARÍA DE FINANZAS
B6: TÍTULOS PÚBLICOS, LETRAS DEL TESORO, PRÉSTAMOS GARANTIZADOS Y PAGARÉS
B7: EMITIDOS EN MONEDA NACIONAL AJUSTABLES POR CER
B8: DATOS AL 31/12/2019
H11: En miles de u$s
B12: Fecha de emisión | C12: Denominación | D12: Tasa Vigente | E12: Vencimiento | F12: Valor nominal original en circulación (1) | G12: Valor nominal residual en circulación (2) | H12: Valor nominal actualizado en circulación (3)
C17: TÍTULOS PÚBLICOS | F17: =+F22+F19+F30+F37 -> 5474876.9 | G17: =+G22+G19+G30+G37 -> 5456394.8 | H17: =+H22+H19+H30+H37 -> 22763419
C19: BONOS DE CONSOLIDACIÓN | F19: =+F20 -> 32271.974 | G19: =+G20 -> 13789.815 | H19: =+H20 -> 214651.46
B20: 38061 | C20: PR13/$+CER/2,00%/15-03-2024 | D20: 0.02 | E20: 2024 | F20: 32271.974 | G20: 13789.815 | H20: 214651.46
C22: BONOS | F22: =SUM(F23:F28) -> 4827535.2 | G22: =SUM(G23:G28) -> 4827535.2 | H22: =SUM(H23:H28) -> 12089128
B23: 42573 | C23: BONCER/$+CER/2,50%/22-07-2021 | D23: 0.025 | E23: 2021 | F23: 958168.98 | G23: 958168.98 | H23: 2860617.6
B24: 42671 | C24: BONCER/$+CER/2,25%/28-04-2020 | D24: 0.0225 | E24: 2020 | F24: 1843244.6 | G24: 1843244.6 | H24: 5238971
B25: 43165 | C25: BONCER/$+CER/4,00%/06-03-2023 | D25: 0.04 | E25: 2023 | F25: 472368.1 | G25: 472368.1 | H25: 1002486.3
B26: 43217 | C26: BONCER/$+CER/4,00%/27-04-2025 | D26: 0.04 | E26: 2025 | F26: 485813.47 | G26: 485813.47 | H26: 991947.64
B27: 43433 | C27: BONCER/$+CER/8,50%/29-11-2022 | D27: 0.085 | E27: 2022 | F27: 567063.53 | G27: 567063.53 | H27: 898390.25
B28: 43165 | C28: BOGATO/$/CER+4%/06-03-2020 | D28: 0.04 | E28: 2020 | F28: 500876.53 | G28: 500876.53 | H28: 1096715.3
C30: BONOS DE LA REESTRUCTURACIÓN - DTO. 1735/04 y 563/10 | F30: =SUM(F31:F35) -> 615069.73 | G30: =SUM(G31:G35) -> 615069.73 | H30: =SUM(H31:H35) -> 10458655
B31: 37986 | C31: PAR/$+CER/TASA FIJA/31-12-2038/DTO. 1735-04 | D31: 0.0118 | E31: 2038 | F31: 47209.898 | G31: 47209.898 | H31: 606032.12
B32: 37986 | C32: PAR/$+CER/TASA FIJA/31-12-2038/DTO. 563-10 | D32: 0.0118 | E32: 2038 | F32: 187.75387 | G32: 187.75387 | H32: 2410.1911
B33: 37986 | C33: DISCOUNT/$+CER/5,83%/31-12-2033/DTO. 1735-04 | D33: 0.0583 | E33: 2033 | F33: 174324.37 | G33: 174324.37 | H33: 2841859.6
B34: 37986 | C34: DISCOUNT/$+CER/5,83%/31-12-2033/DTO. 563-10 | D34: 0.0583 | E34: 2033 | F34: 2095.509 | G34: 2095.509 | H34: 34161.257
B35: 37986 | C35: CUASIPAR/$+CER/3,31%/31-12-2045/DTO. 1735-04 | D35: 0.0331 | E35: 2045 | F35: 391252.2 | G35: 391252.2 | H35: 6974192.2
C37: AMPAROS Y EXCEPCIONES | H37: 984.37376
C39: LETRAS DEL TESORO | F39: =SUM(F41:F42) -> 874651.24 | G39: =SUM(G41:G42) -> 524790.74 | H39: =SUM(H41:H42) -> 733141.89
B41: 43524 | C41: LETES/$+CER/ 30-08-2019 | D41: Tasa Cero | E41: 2019 | F41: 130146.91 | G41: 78088.149 | H41: 112110.57
B42: 43553 | C42: LETES/$+CER/ 30-09-2019 | D42: Tasa Cero | E42: 2019 | F42: 744504.33 | G42: 446702.6 | H42: 621031.32
C44: PRÉSTAMOS GARANTIZADOS | F44: =+F46 -> 28907.881 | G44: =+G46 -> 28907.881 | H44: =+H46 -> 640325.05
C46: PRÉSTAMOS TASA FIJA 5,00% | F46: =SUM(F47:F56) -> 28907.881 | G46: =SUM(G47:G56) -> 28907.881 | H46: =SUM(H47:H56) -> 640325.05
B47: 37201 | C47: PTMO. GAR. TASA FIJA BONTE 27 | D47: 0.05 | E47: 2027 | F47: 977.74441 | G47: 977.74441 | H47: 18741.842
B48: 37201 | C48: PTMO. GAR. TASA FIJA GL 20 | D48: 0.05 | E48: 2020 | F48: 600.81081 | G48: 600.81081 | H48: 11517.814
B49: 37201 | C49: PTMO. GAR. TASA FIJA GL 27 | D49: 0.05 | E49: 2027 | F49: 2778.1902 | G49: 2778.1902 | H49: 53237.009
B50: 37201 | C50: PTMO. GAR. TASA FIJA GL 30 | D50: 0.05 | E50: 2030 | F50: 210.639 | G50: 210.639 | H50: 4038.0449
B51: 37201 | C51: PTMO. GAR. TASA FIJA GL 31 | D51: 0.05 | E51: 2031 | F51: 48.244428 | G51: 48.244428 | H51: 924.86747
B52: 37201 | C52: PTMO. GAR. TASA FIJA GL 31 MEGA | D52: 0.05 | E52: 2031 | F52: 15759.473 | G52: 15759.473 | H52: 372055.18
B53: 37201 | C53: PTMO. GAR. TASA VAR. GL 20 | D53: 0.05 | E53: 2020 | F53: 277.31584 | G53: 277.31584 | H53: 5294.5222
B54: 37201 | C54: PTMO. GAR. TASA VAR. GL 27 | D54: 0.05 | E54: 2027 | F54: 2844.9682 | G54: 2844.9682 | H54: 54299.111
B55: 37201 | C55: PTMO. GAR. TASA VAR. GL 30 | D55: 0.05 | E55: 2030 | F55: 1582.3684 | G55: 1582.3684 | H55: 30210.623
B56: 37201 | C56: PTMO. GAR. TASA VAR. GL 31 MEGA | D56: 0.05 | E56: 2031 | F56: 3828.1263 | G56: 3828.1263 | H56: 90006.028
...

Sheet A.1.9
A1: Indice
B2: =+INDICE!B2 -> MINISTERIO DE ECONOMÍA
B3: SECRETARÍA DE FINANZAS
B6: TÍTULOS PÚBLICOS, LETRAS DEL TESORO Y PAGARÉS
B7: EMITIDOS EN MONEDA EXTRANJERA
B8: DATOS AL 31/12/2019
H11: En miles de u$s
B12: Fecha de emisión | C12: Denominación | D12: Tasa vigente | E12: Vencimiento | F12: Valor nominal original en circulación | G12: Valor nominal residual en circulación (1) | H12: Valor nominal actualizado en circulación (2)
C18: TÍTULOS PÚBLICOS | F18: =+F20+F48+F66 -> 1.0126828e+08 | G18: =+G20+G48+G66 -> 99942077 | H18: =+H20+H48+H66 -> 1.0541618e+08
C20: BONOS | F20: =SUM(F21:F46) -> 73226561 | G20: =SUM(G21:G46) -> 71900356 | H20: =SUM(H21:H46) -> 71900356
B21: 41766 | C21: BONAR/U$S/8,75%/07-05-2024 | D21: 0.0875 | E21: 2024 | F21: 7960418.5 | G21: 6634212.8 | H21: 6634212.8
B22: 42285 | C22: BONAR/U$S/8,00%/08-10-2020 | D22: 0.08 | E22: 2020 | F22: 2947560.7 | G22: 2947560.7 | H22: 2947560.7
B23: 42368 | C23: BONAR/U$S/7,75 %/30-12-2022 | D23: 0.0775 | E23: 2022 | F23: 4497753.4 | G23: 4497753.4 | H23: 4497753.4
B24: 42368 | C24: BONAR/U$S/7,875%/30-12-2025 | D24: 0.07875 | E24: 2025 | F24: 4510462.6 | G24: 4510462.6 | H24: 4510462.6
B25: 42368 | C25: BONAR/U$S/7,875%/30-12-2027 | D25: 0.07875 | E25: 2027 | F25: 4690499.6 | G25: 4690499.6 | H25: 4690499.6
B26: 42482 | C26: BIRAD/U$S/6,875%/22-04-2021 | D26: 0.06875 | E26: 2021 | F26: 4500000 | G26: 4500000 | H26: 4500000
B27: 42482 | C27: BIRAD/U$S/7,50%/22-04-2026 | D27: 0.075 | E27: 2026 | F27: 6500000 | G27: 6500000 | H27: 6500000
B28: 42482 | C28: BIRAD/U$S/7,625%/22-04-2046 | D28: 0.07625 | E28: 2046 | F28: 2750000 | G28: 2750000 | H28: 2750000
B29: 42557 | C29: BIRAD/U$S/6,625%/06-07-2028 | D29: 0.06625 | E29: 2028 | F29: 1000000 | G29: 1000000 | H29: 1000000
B30: 42557 | C30: BIRAD/U$S/7,125%/06-07-2036 | D30: 0.07125 | E30: 2036 | F30: 1750000 | G30: 1750000 | H30: 1750000
B31: 42587 | C31: BONAR/U$S/1,00%/05-08-2023 | D31: 0.01 | E31: 2023 | F31: 694687.19 | G31: 694687.19 | H31: 694687.19
B32: 42655 | C32: BIRAE/EUR/3,875%/15-01-2022 | D32: 0.03875 | E32: 2022 | F32: 1401188.2 | G32: 1401188.2 | H32: 1401188.2
... B46: 43433 | C46: BONAR/U$S/8,00%/29-05-2020 | D46: 0.08 | E46: 2020 | F46: 2120284.8 | G46: 2120284.8 | H46: 2120284.8
C48: BONOS DE LA REESTRUCTURACIÓN - DTO. 1735/04 y 563/10 | F48: =SUM(F49:F64) -> 28041721 | G48: =SUM(G49:G64) -> 28041721 | H48: =SUM(H49:H64) -> 33502040
B49: 37986 | C49: PAR/U$S/TASA FIJA/31-12-2038/DTO. 1735-04/LEY NY | D49: 0.025 | E49: 2038 | F49: 5296689.2 | G49: 5296689.2 | H49: 5296689.2
B50: 37986 | C50: PAR/U$S/TASA FIJA/31-12-2038/DTO. 1735-04/LEY ARG | D50: 0.025 | E50: 2038 | F50: 1229562.8 | G50: 1229562.8 | H50: 1229562.8
B51: 37986 | C51: PAR/U$S/TASA FIJA/31-12-2038/DTO. 563-10/LEY NY | D51: 0.025 | E51: 2038 | F51: 96939.179 | G51: 96939.179 | H51: 96939.179
B52: 37986 | C52: PAR/U$S/TASA FIJA/31-12-2038/DTO. 563-10/LEY ARG | D52: 0.025 | E52: 2038 | F52: 71439.702 | G52: 71439.702 | H52: 71439.702
B53: 37986 | C53: PAR/EUR/TASA FIJA/31-12-2038/DTO. 1735-04 | D53: 0.0226 | E53: 2038 | F53: 5643887.6 | G53: 5643887.6 | H53: 5643887.6
B54: 37986 | C54: PAR/EUR/TASA FIJA/31-12-2038/DTO. 563-10 | D54: 0.0226 | E54: 2038 | F54: 1612275.5 | G54: 1612275.5 | H54: 1612275.5
B55: 37986 | C55: PAR/JPY/TASA FIJA/31-12-2038/DTO. 1735-04 | D55: 0.0045 | E55: 2038 | F55: 158959.98 | G55: 158959.98 | H55: 158959.98
B56: 37986 | C56: PAR/JPY/TASA FIJA/31-12-2038/DTO. 563-10 | D56: 0.0045 | E56: 2038 | F56: 7861.9188 | G56: 7861.9188 | H56: 7861.9188
B57: 37986 | C57: DISCOUNT/USD/8,28%/31-12-2033/DTO. 1735-04/LEY NY | D57: 0.0828 | E57: 2033 | F57: 3039534.1 | G57: 3039534.1 | H57: 4261542.4
B58: 37986 | C58: DISCOUNT/USD/8,28%/31-12-2033/DTO. 1735-04/LEY ARG | D58: 0.0828 | E58: 2033 | F58: 5042239.3 | G58: 5042239.3 | H58: 7069411
B59: 37986 | C59: DISCOUNT/USD/8,28%/31-12-2033/DTO. 563-10/LEY NY | D59: 0.0828 | E59: 2033 | F59: 929895.89 | G59: 929895.89 | H59: 1303749.4
B60: 37986 | C60: DISCOUNT/USD/8,28%/31-12-2033/DTO. 563-10/LEY ARG | D60: 0.0828 | E60: 2033 | F60: 131475.87 | G60: 131475.87 | H60: 184334.17
... B64: 37986 | C64: DISCOUNT/JPY/4,33%/31-12-2033/DTO. 563-10 | D64: 0.0433 | E64: 2033 | F64: 23468.926 | G64: 23468.926 | H64: 28045.026
C66: AMPAROS | H66: 13780.741
C68: LETRAS DEL TESORO | F68: =SUM(F70:F90) -> 19871845 | G68: =SUM(G70:G90) -> 18194684 | H68: =SUM(H70:H90) -> 18194684
B70: 43693 | C70: LETRA/U$S/MENDOZA/28-10-2024 | D70: Tasa Cero | E70: 2024 | F70: 1023362.9 | G70: 1016367.1 | H70: 1016367.1
...

Sheet A.1.10
A1: Indice
B2: =+INDICE!B2 -> MINISTERIO DE ECONOMÍA
B3: SECRETARÍA DE FINANZAS
B6: DEUDA ELEGIBLE PENDIENTE DE REESTRUCTURACIÓN
B7: DATOS AL 31/12/2019
G10: En miles de u$s
B11: Denominación | C11: Moneda de origen | D11: Capital | E11: Atrasos de Interés (1) | F11: Intereses Compensatorios (2) | G11: Total
B17: EN MONEDA NACIONAL | D17: =SUM(D19:D32) -> 465.31161 | E17: =SUM(E19:E32) -> 44.363588 | F17: =SUM(F19:F32) -> 18.509755 | G17: =SUM(G19:G32) -> 528.18495
B19: BOCON PRE.2ºS./$/C.A./02/PRE3 | C19: Pesos | D19: 8.3416876 | E19: 0.073085177 | F19: 0.83325726 | G19: 9.2480301
B20: BOCON PRO.1ºS./$/C.A./07/PRO1 | C20: Pesos | D20: 149.05736 | E20: 9.8806977 | F20: 4.8392153 | G20: 163.77727
B21: BOCON PRO.2ºS./$/C.A./10/PRO3 | C21: Pesos | D21: 2.3879482 | E21: 0.24163676 | F21: 0.033840825 | G21: 2.6634258
B22: BOCON PRO.3ºS./$/C.A./07/PRO5 | C22: Pesos | D22: 100.53328 | E22: 7.6518143 | F22: 3.3670275 | G22: 111.55212
B23: BOCON PRO.5°S./$/C.A./07/PRO9 | C23: Pesos | D23: 103.05192 | E23: 10.843749 | F23: 3.4011232 | G23: 117.29679
B24: EUROLETRA/$/11,75%/2007 | C24: Pesos | D24: 5.342683 | E24: 3.4527089 | F24: 5.7719528 | G24: 14.567345
B25: EUROLETRA/$/8,75%/2002 | C25: Pesos | D25: 0.21834878 | E25: 0.016895519 | F25: 0.26333772 | G25: 0.49858202
B26: Dto.1023/7-7-95/CHACO | C26: Pesos | D26: 0.041783621 | E26: 0.0076881209 | F26: 0 | G26: 0.049471742
B27: Dto.1023/7-7-95/CHUBUT | C27: Pesos | D27: 1.8151488 | E27: 0.14494165 | F27: 0 | G27: 1.9600905
B28: Dto.1023/7-7-95/CHUBUT | C28: Pesos | D28: 16.247123 | E28: 0.69301878 | F28: 0 | G28: 16.940142
B29: Dto.1023/7-7-95/RIO NEGRO | C29: Pesos | D29: 2.5751049 | E29: 0.20593722 | F29: 0 | G29: 2.7810422
B30: Dto.1023/7-7-95/SALTA | C30: Pesos | D30: 3.2668446 | E30: 0.26125687 | F30: 0 | G30: 3.5281015
... B32: Dto.1023/7-7-95/M.C.B.A. | C32: Pesos | D32: 72.12782 | E32: 10.865801 | F32: 0 | G32: 82.993621
B34: EN MONEDA NACIONAL AJUSTABLE POR CER | D34: =+SUM(D36:D59) -> 50997.461 | E34: =+SUM(E36:E59) -> 1866.46 | F34: =+SUM(F36:F59) -> 9791.7633 | G34: =+F34+E34+D34 -> 62655.684
B36: LETES/U$S/15-3-2002(P) | C36: Pesos Ajustados por CER | D36: 4548.8711 | E36: 0 | F36: 0 | G36: 4548.8711
B37: LETES/U$S/15-2-2002(P) | C37: Pesos Ajustados por CER | D37: 1580.8115 | E37: 0 | F37: 0 | G37: 1580.8115
B38: LETES/U$S/8-3-2002(P) | C38: Pesos Ajustados por CER | D38: 1601.9284 | E38: 0 | F38: 0 | G38: 1601.9284
B39: LETES/U$S/22-2-2002(P) | C39: Pesos Ajustados por CER | D39: 354.9246 | E39: 0 | F39: 0 | G39: 354.9246
B40: LETES/U$S/22-3-2002(P) | C40: Pesos Ajustados por CER | D40: 387.24615 | E40: 0 | F40: 0 | G40: 387.24615
B41: BONEX/1992(P) | C41: Pesos Ajustados por CER | D41: 3250.6306 | E41: 25.518818 | F41: 884.35211 | G41: 4160.5015
B42: FERROBONOS(P) | C42: Pesos Ajustados por CER | D42: 2.8093657 | E42: 0.81975167 | F42: 0 | G42: 3.6291174
B43: PRE4(P) | C43: Pesos Ajustados por CER | D43: 1220.3061 | E43: 25.189669 | F43: 333.07576 | G43: 1578.5715
B44: PRO2(P) | C44: Pesos Ajustados por CER | D44: 5664.526 | E44: 302.85787 | F44: 1026.8527 | G44: 6994.2366
B45: PRO4(P) | C45: Pesos Ajustados por CER | D45: 2075.7873 | E45: 210.26711 | F45: 220.72538 | G45: 2506.7797
B46: PRO6(P) | C46: Pesos Ajustados por CER | D46: 5301.9767 | E46: 325.07837 | F46: 929.90781 | G46: 6556.9629
B47: PRO8(P) | C47: Pesos Ajustados por CER | D47: 101.50555 | E47: 10.076234 | F47: 0.63159012 | G47: 112.21338
... B59: BONO/U$S/ENC.+4.35%/2004(P) | C59: Pesos Ajustados por CER | D59: 43.71193 | E59: 2.0157443 | F59: 10.661952 | G59: 56.389626
B61: EN MONEDA EXTRANJERA | D61: =+SUM(D63:D82)+SUM(D103:D177) -> 1006617 | E61: =+SUM(E63:E82)+SUM(E103:E177) -> 861946.75 | F61: =+SUM(F63:F82)+SUM(F103:F177) -> 503461.94 | G61: =+F61+E61+D61 -> 2372025.7
B63: EUROLETRA/CHF/7%/2003 | C63: CHF | D63: 7744.3687 | E63: 1084.2116 | F63: 6717.5945 | G63: 15546.175
B64: DISCOUNT/DEM/L.+0,8125%/2023 | C64: EUR | D64: 280.83513 | E64: 90.792044 | F64: 32.209917 | G64: 403.83709
B65: PAR BONDS/DEM/5,87%/2023 | C65: EUR | D65: 3765.4833 | E65: 2873.4403 | F65: 1071.7465 | G65: 7710.6702
B66: EUROLETRA/EUR/8,75%/2003 | C66: EUR | D66: 4202.8864 | E66: 735.50513 | F66: 4860.4631 | G66: 9798.8546
...

Sheet A.2.1
A1: Indice
B2: =+INDICE!B2 -> MINISTERIO DE ECONOMÍA
B3: =+A.1.10!B3 -> SECRETARÍA DE FINANZAS
B6: DEUDA BRUTA DE LA ADMINISTRACIÓN CENTRAL
B7: SERIE POR TRIMESTRE Y POR INSTRUMENTO
B10: En miles de u$s - TC del trimestre
B11: INSTRUMENTO | C11: 2018 | D11: 2019
C12: Saldo al 31/12/2018 | D12: Saldo al 31/03/2019 | E12: Saldo al 30/06/2019 | F12: Saldo al 30/09/2019 | G12: Saldo al 31/12/2019
B14: I- DEUDA BRUTA + VALORES NEGOCIABLES VINCULADOS AL PBI ( II+VII ) | C14: =+C17+C74 -> 3.4538474e+08 | D14: =+D17+D74 -> 3.3792935e+08 | E14: =+E17+E74 -> 3.5038828e+08 | F14: =+F17+F74 -> 3.2403783e+08 | G14: =+G17+G74 -> 3.3602735e+08
B17: II- DEUDA BRUTA ( III+IV+V+VI ) | C17: =+C20+C53+C61+C66 -> 3.321918e+08 | D17: =+D20+D53+D61+D66 -> 3.2489795e+08 | E17: =+E20+E53+E61+E66 -> 3.3726739e+08 | F17: =+F20+F53+F61+F66 -> 3.1125103e+08 | G17: =+G20+G53+G61+G66 -> 3.2306462e+08
B20: III- MEDIANO Y LARGO PLAZO | C20: =+C22+C26+C28+C51 -> 2.9054808e+08 | D20: =+D22+D26+D28+D51 -> 2.8821517e+08 | E20: =+E22+E26+E28+E51 -> 3.0086194e+08 | F20: =+F22+F26+F28+F51 -> 2.9350376e+08 | G20: =+G22+G26+G28+G51 -> 3.0116072e+08
B22: TÍTULOS PÚBLICOS | C22: =+C23+C24 -> 2.1525157e+08 | D22: =+D23+D24 -> 2.1332991e+08 | E22: =+E23+E24 -> 2.1482729e+08 | F22: =+F23+F24 -> 1.9100641e+08 | G22: =+G23+G24 -> 1.9415281e+08
B23: - Moneda nacional | C23: 43400131 | D23: 41502108 | E23: 47617911 | F23: 37459863 | G23: 38723467
B24: - Moneda extranjera | C24: 1.7185144e+08 | D24: 1.718278e+08 | E24: 1.6720938e+08 | F24: 1.5354655e+08 | G24: 1.5542934e+08
B26: LETRAS DEL TESORO (1) | C26: 11555685 | D26: 12306696 | E26: 13735015 | F26: 26559882 | G26: 23113729
B28: PRÉSTAMOS | C28: =+C30+C32+C43+C45+C47+C49 -> 61262527 | D28: =+D30+D32+D43+D45+D47+D49 -> 60737869 | E28: =+E30+E32+E43+E45+E47+E49 -> 71211255 | F28: =+F30+F32+F43+F45+F47+F49 -> 75351975 | G28: =+G30+G32+G43+G45+G47+G49 -> 79052379
B30: PRÉSTAMOS GARANTIZADOS | C30: 683538.52 | D30: 637850.15 | E30: 729146.87 | F30: 584431.07 | G30: 640325.05
B32: ORGANISMOS INTERNACIONALES | C32: =SUM(C33:C41) -> 51037436 | D32: =SUM(D33:D41) -> 50871977 | E32: =SUM(E33:E41) -> 62752778 | F32: =SUM(F33:F41) -> 67389879 | G32: =SUM(G33:G41) -> 68000788
B33: - BCIE | C33: 2625 | D33: 2625 | E33: 2625 | F33: 2625 | G33: 2625
B34: - BIRF | C34: 6879346 | D34: 6802881.8 | E34: 6960726.8 | F34: 7060899.9 | G34: 7127849.6
B35: - BID | C35: 12331943 | D35: 12176419 | E35: 12911927 | F35: 12756148 | G35: 12646999
B36: - FONPLATA | C36: 167338.58 | D36: 193602.05 | E36: 205327.1 | F36: 211076.42 | G36: 237350.83
B37: - FIDA | C37: 45161.6 | D37: 44668.879 | E37: 42243.593 | F37: 40925.303 | G37: 41144.733
B38: - CAF | C38: 3467422.1 | D38: 3475803 | E38: 3557602.7 | F38: 3662650.5 | G38: 3655847.8
B39: - OFID | C39: 41262.805 | D39: 42507.082 | E39: 55733.582 | F39: 60890.877 | G39: 74644.737
B40: - FMI | C40: 28031771 | D40: 28062904 | E40: 38940381 | F40: 43508807 | G40: 44128471
B41: - BEI | C41: 70566 | D41: 70566 | E41: 76211.278 | F41: 85856.372 | G41: 85856.372
B43: ORGANISMOS OFICIALES | C43: 6912168.6 | D43: 6869745 | E43: 5320477.2 | F43: 5289399.3 | G43: 5398072.3
B45: BANCA COMERCIAL | C45: 1194162.8 | D45: 1140918.9 | E45: 1187129 | F45: 972022.71 | G45: 2284020.7
B47: AVALES | C47: 931193.36 | D47: 871628.7 | E47: 831158.82 | F47: 811485.5 | G47: 2396978.6
... B51: ADELANTOS TRANSITORIOS BCRA | C51: 2478291.8 | D51: 1840690.3 | E51: 1088382.8 | F51: 585493.32 | G51: 4841806.5
B53: IV- CORTO PLAZO | C53: =SUM(C55:C59) -> 38733469 | D53: =SUM(D55:D59) -> 34101861 | E53: =SUM(E55:E59) -> 33844412 | F53: =SUM(F55:F59) -> 15238796 | G53: =SUM(G55:G59) -> 19364729
B55: ADELANTOS TRANSITORIOS BCRA | C55: 10818524 | D55: 9755428.1 | E55: 10754965 | F55: 8148781.3 | G55: 9395275.1
B56: LETRAS DEL TESORO | C56: 22694282 | D56: 22346432 | E56: 23089447 | F56: 7090014.6 | G56: 8177985.1
B57: PAGARÉS DEL TESORO | C57: 1013005.1 | D57: 0 | E57: 0 | F57: 0 | G57: 1290591.9
B58: BANCA COMERCIAL | C58: 0 | D58: 0 | E58: 0 | F58: 0 | G58: 500876.53
B59: TÍTULOS PÚBLICOS | C59: 4207658.3 | D59: 2000000 | E59: 0 | F59: 0 | G59: 0
B61: V- DEUDA EN SITUACIÓN DE PAGO DIFERIDO | C61: =+C63+C64 -> 104835.13 | D61: =+D63+D64 -> 104084.63 | E61: =+E63+E64 -> 104717.07 | F61: =+F63+F64 -> 102962.75 | G61: =+G63+G64 -> 103955.23
B63: CAPITAL | C63: 96391.014 | D63: 95790.927 | E63: 96324.436 | F63: 94889.592 | G63: 95681.181
B64: INTERÉS (2) | C64: 8444.1139 | D64: 8293.7073 | E64: 8392.6373 | F64: 8073.1588 | G64: 8274.0532
...

Sheet A.2.2
A1: Indice
B2: =+INDICE!B2 -> MINISTERIO DE ECONOMÍA
B3: =+A.2.1!B3 -> SECRETARÍA DE FINANZAS
B5: DEUDA BRUTA DE LA ADMINISTRACIÓN CENTRAL
B6: FLUJOS Y VARIACIONES
B7: 4to. TRIMESTRE DE 2019
C10: Miles de u$s | D10: Miles de $
B12: I - DEUDA BRUTA (EXCLUIDA LA ELEGIBLE PENDIENTE DE REESTRUCTURACIÓN), AL 30/09/2019 | C12: 3.0884552e+08 | D12: 1.7776623e+10
B14: II - DEUDA ELEGIBLE PENDIENTE DE REESTRUCTURACIÓN, AL 30/09/2019 | C14: 2405504.3 | D14: 1.3845674e+08
B16: III - DEUDA BRUTA, AL 30/09/2019 (I + II) | C16: =+C12+C14 -> 3.1125103e+08 | D16: =+D12+D14 -> 1.791508e+10
B18: VARIACIONES
B20: 1 - Financiamiento | C20: =SUM(C22:C30) -> 21200127 | D20: =SUM(D22:D30) -> 1.2202433e+09
B22: Adelantos Transitorios del BCRA | C22: 10381648 | D22: 597550000
B23: Préstamos Organismos Multilaterales | C23: 435124.03 | D23: 25045000
B24: Financiamiento Banco Nación | C24: 521210.67 | D24: 30000000
B25: Letras del Tesoro - Organismos Públicos | C25: 5466299.1 | D25: 3.1463088e+08
B26: Letras Intransferibles | C26: 1326575.8 | D26: 76355450
B27: Titulos del Tesoro | C27: 144327.23 | D27: 8307229.8
B28: Pagarés del Tesoro | C28: 1342986.2 | D28: 77300000
B29: Préstamos Organismos Oficiales | C29: 109171.73 | D29: 6283739
B30: Otros | C30: 1472784.7 | D30: 84770981
B32: 2 - Amortizaciones y Cancelaciones | C32: =SUM(C34:C40) -> 13374942 | D32: =SUM(D34:D40) -> 7.6983891e+08
B34: Adelantos Transitorios del BCRA | C34: 4300856.7 | D34: 247550000
B35: Préstamos Organismos Multilaterales | C35: 443857.17 | D35: 25547664
B36: Letras del Tesoro - Organismos Públicos | C36: 8321430.6 | D36: 4.789674e+08
B37: Titulos del Tesoro | C37: 174333.73 | D37: 10034353
B38: Préstamos Organismos Oficiales | C38: 28151.374 | D38: 1620345.3
B39: Bonos de Consolidación | C39: 19145.469 | D39: 1101980.6
B40: Otros | C40: 87166.706 | D40: 5017167.4
B42: a) Financiamiento, neto de amortizaciones ( 1 - 2 ) | C42: =+C20-C32 -> 7825185.5 | D42: =+D20-D32 -> 4.5040437e+08
B44: b) Emisión Bonos de Consolidación | C44: 8873.7458 | D44: 510757.72
B46: c) Avales netos de cancelaciones | C46: -399408.81 | D46: -22989292
B48: d) Letras en garantía | C48: -48686.05 | D48: -2802286.3
B50: e) Ajustes de valuación - Excluyendo la deuda elegible pendiente de reestructuración | C50: =SUM(C52:C55) -> 4397922.7 | D50: =SUM(D52:D55) -> 1.0023517e+09
B52: Tipo de Cambio (excluye deudas ajustables por CER) | C52: -585454.26 | D52: 6.6094132e+08
B53: Variación de la deuda ajustable por CER (efectos tipo de cambio y CER) | C53: 2038734.3 | D53: 1.7192175e+08
B54: Capitalización de Bonos del Canje, Préstamos Garantizados, Pagaré Banco Nación, Bonos de consolidación y Otros | C54: 933485.55 | D54: 53729841
B55: Otras Operaciones (Registro CCF, amparos y excepciones y otros ajustes (1)) | C55: 2011157.1 | D55: 1.1575879e+08
B57: f) Ajustes de valuación sobre deuda elegible pendiente de reestructuración | C57: =SUM(C59:C61) -> 29705.226 | D57: =SUM(D59:D61) -> 7400136.4
B59: Tipo de Cambio (excluye deudas ajustables por CER) | C59: 24328.721 | D59: 6944266.4
...

Sheet A.2.3
A1: Indice
B2: =+INDICE!B2 -> MINISTERIO DE ECONOMÍA
B3: =+INDICE!B3 -> SECRETARÍA DE FINANZAS
B5: DEUDA BRUTA DE LA ADMINISTRACIÓN CENTRAL
B6: FLUJOS Y VARIACIONES
B7: ACUMULADO ENERO 2019 - DICIEMBRE 2019
C10: Miles de u$s | D10: Miles de $
B12: I - DEUDA BRUTA (EXCLUIDA LA ELEGIBLE PENDIENTE DE REESTRUCTURACIÓN), AL 31/12/2018 | C12: 3.2938638e+08 | D12: 1.2453539e+10
B14: II - DEUDA ELEGIBLE PENDIENTE DE REESTRUCTURACIÓN, AL 31/12/2018 | C14: 2805421.7 | D14: 1.0606823e+08
B16: III - DEUDA BRUTA, AL 31/12/2018 (I + II) | C16: =+C12+C14 -> 3.321918e+08 | D16: =+D12+D14 -> 1.2559607e+10
B18: VARIACIONES
B20: 1 - Financiamiento | C20: =SUM(C22:C30) -> 98622529 | D20: =SUM(D22:D30) -> 4.4245842e+09
B22: Adelantos Transitorios del BCRA | C22: 16636408 | D22: 852730000
B23: Préstamos Organismos Multilaterales | C23: 18918031 | D23: 8.1949079e+08
B24: Financiamiento Banco Nación | C24: 521210.67 | D24: 30000000
B25: Letras del Tesoro - Organismos Públicos | C25: 43732272 | D25: 1.8947768e+09
B26: Letras Intransferibles | C26: 1326575.8 | D26: 76355450
B27: Títulos del Tesoro | C27: 14081049 | D27: 5.6331524e+08
B28: Pagarés del Tesoro | C28: 1342986.2 | D28: 77300000
B29: Préstamos Organismos Oficiales | C29: 416295.65 | D29: 18890657
B30: Otros | C30: 1647700.4 | D30: 91725246
B32: 2 - Amortizaciones y Cancelaciones | C32: =SUM(C34:C43) -> 93179644 | D32: =SUM(D34:D43) -> 4.0643922e+09
B34: Adelantos Transitorios del BCRA | C34: 10555617 | D34: 502730000
B35: Préstamos Organismos Multilaterales | C35: 1799300.9 | D35: 81347538
B36: Letras del Tesoro - Organismos Públicos | C36: 45373246 | D36: 2.011786e+09
B37: Títulos del Tesoro | C37: 29450764 | D37: 1.2137924e+09
B38: Bonos Internacionales | C38: 2750000 | D38: 1.1922157e+08
B39: Pagarés del Tesoro | C39: 1170622.6 | D39: 44327786
B40: Préstamos Organismos Oficiales | C40: 1909006.6 | D40: 82436343
B41: Bonos de Consolidación | C41: 68455.385 | D41: 3144632.1
B42: Préstamos Garantizados | C42: 14253.971 | D42: 538918.42
B43: Otros | C43: 88377.19 | D43: 5066880.1
B45: a) Financiamiento, neto de amortizaciones ( 1 - 2 ) | C45: =+C20-C32 -> 5442885 | D45: =+D20-D32 -> 3.6019207e+08
B47: b) Emisión Bonos de Consolidación | C47: 44839.791 | D47: 2015756.2
B49: c) Avales netos de cancelaciones | C49: -479083.05 | D49: -26202778
B51: d) Letras en garantía | C51: -48686.05 | D51: -2802286.3
B53: e) Ajustes de valuación - Excluyendo la deuda elegible pendiente de reestructuración | C53: =SUM(C55:C58) -> -13716928 | D53: =SUM(D55:D58) -> 6.4173565e+09
B55: Tipo de Cambio (excluye deudas ajustables por CER) | C55: -20432016 | D55: 5.5711371e+09
B56: Variación de la deuda ajustable por CER (efectos tipo de cambio y CER) | C56: -1060268 | D56: 4.8063782e+08
B57: Capitalización de Bonos del Canje, Préstamos Garantizados, Pagaré Banco Nación, Bonos de consolidación y Otros | C57: 5738018.1 | D57: 2.4869593e+08
...

Sheet A.2.4
A1: Indice
B2: =+INDICE!B2 -> MINISTERIO DE ECONOMÍA
B3: SECRETARÍA DE FINANZAS
B6: Serie de Tipos de Cambio y Coeficiente de Estabilización de Referencia (CER)
B9: Fecha | C9: CER | D9: Coeficiente de pesificación (1) | E9: U$S / Peso | F9: Euro (Ref) / Peso
B10: 37290 | C10: 1 | D10: 1.399959 | E10: 1.4 | F10: 1.2064
B11: 37346 | C11: 1.0481 | D11: 1.4673678 | E11: 2.9 | F11: 2.5363
B12: 37437 | C12: 1.2495 | D12: 1.7492374 | E12: 3.8 | F12: 3.7549
B13: 37529 | C13: 1.3716 | D13: 1.9202837 | E13: 3.75 | F13: 3.6942
B14: 37621 | C14: 1.4053 | D14: 1.967407 | E14: 3.4 | F14: 3.5409
B15: 37711 | C15: 1.4341 | D15: 2.00774 | E15: 2.88 | F15: 3.1359
B16: 37802 | C16: 1.4404 | D16: 2.01656 | E16: 2.8 | F16: 3.2225
B17: 37894 | C17: 1.4448 | D17: 2.02272 | E17: 2.915 | F17: 3.397
B18: 37986 | C18: 1.4568 | D18: 2.03952 | E18: 2.9175 | F18: 3.6721
B19: 38077 | C19: 1.4678 | D19: 2.05492 | E19: 2.86 | F19: 3.5174
B20: 38168 | C20: 1.4983 | D20: 2.09762 | E20: 2.958 | F20: 3.6029
B21: 38260 | C21: 1.52 | D21: 2.128 | E21: 2.981 | F21: 3.7073
... B82: 43830 | C82: 18.7009 | D82: 26.18126 | E82: 59.895 | F82: 67.139334
B84: (1) Factor de conversión de dólares a pesos aplicable cuando a las obligaciones corresponde pesificarlas a un valor de 1,40 más CER (por ejemplo, depósitos bancarios y deudas del sector público, en dólares, con legislación nacional).

Sheet A.2.5
A1: Indice
B2: =+INDICE!B2 -> MINISTERIO DE ECONOMÍA
B3: =+INDICE!B3 -> SECRETARÍA DE FINANZAS
B6: SERIE DE DEUDA DEL SECTOR PÚBLICO NACIONAL
B7: POR AÑO Y POR INSTRUMENTO
B8: AJUSTADO POR OPERACIONES CON FECHA VALOR
B10: En millones de u$s - TC de fin de cada año
B11: INSTRUMENTO | C11: Saldo
C12: 31/12/92 (*) | D12: 34334 | E12: 34699 | F12: 35064 | G12: 35430 | H12: 35795 | I12: 36160 | J12: 36525 | K12: 36891 | L12: 37256 | M12: 37621 | N12: 37986 | O12: 38352 | P12: 38717 | Q12: 39082 | R12: 39447 | S12: 39813 | T12: 40178 | U12: 40543 | V12: 40908 | W12: 41274 | X12: 41639 | Y12: 42004 | Z12: 42369 | AA12: 42735 | AB12: 43100 | AC12: 43465 | AD12: 43830
B14: DEUDA PÚBLICA BRUTA + VALORES NEGOCIABLES VINCULADOS AL PBI (I + V) | C14: =+C17+C50 -> 63250 | D14: =+D17+D50 -> 71112 | E14: =+E17+E50 -> 81820 | F14: =+F17+F50 -> 88711 | G14: =+G17+G50 -> 99046 | H14: =+H17+H50 -> 103718 | I14: =+I17+I50 -> 114134 | J14: =+J17+J50 -> 123366 | ... AD14: =+AD17+AD50 -> 336027.35
B17: I- TOTAL DEUDA PÚBLICA BRUTA ( II+III +IV) | C17: =+C20+C38+C40 -> 63250 | D17: =+D20+D38+D40 -> 71112 | E17: =+E20+E38+E40 -> 81820 | F17: =+F20+F38+F40 -> 88711 | G17: =+G20+G38+G40 -> 99046 | H17: =+H20+H38+H40 -> 103718 | I17: =+I20+I38+I40 -> 114134 | J17: =+J20+J38+J40 -> 123366 | ... AD17: =+AD20+AD38+AD40 -> 323064.62
B20: II- DEUDA A VENCER | C20: =+C22+C24+C36 -> 54018 | D20: =+D22+D24+D36 -> 71112 | E20: =+E22+E24+E36 -> 81820 | F20: =+F22+F24+F36 -> 88711 | G20: =+G22+G24+G36 -> 99046 | H20: =+H22+H24+H36 -> 103718 | I20: =+I22+I24+I36 -> 114134 | J20: =+J22+J24+J36 -> 123366 | ... AD20: =+AD22+AD24+AD36 -> 320525.45
B22: TÍTULOS PUBLICOS Y LETRAS DEL TESORO | C22: 17184 | D22: 48401 | E22: 57109 | F22: 59048 | G22: 69393 | H22: 74801 | I22: 82363 | J22: 91555 | K22: 98895 | L22: 83051 | M22: 91656 | N22: 96885 | O22: 92224 | P22: 75628 | Q22: 92222 | R22: 99208 | S22: 99994 | T22: 100719 | U22: 115672 | V22: 125391 | W22: 133214 | X22: 137809 | Y22: 154775 | Z22: 160150 | AA22: 208400.33 | AB22: 256515.52 | AC22: 253709.2 | AD22: 225444.52
B24: PRÉSTAMOS | C24: =SUM(C26:C34) -> 36834 | D24: =SUM(D26:D34) -> 22711 | E24: =SUM(E26:E34) -> 24711 | F24: =SUM(F26:F34) -> 29663 | G24: =SUM(G26:G34) -> 29653 | H24: =SUM(H26:H34) -> 28917 | I24: =SUM(I26:I34) -> 31771 | J24: =SUM(J26:J34) -> 31811 | ... AD24: =SUM(AD26:AD34) -> 80843.847
B26: PRÉSTAMOS GARANTIZADOS | C26: 0 | D26: 0 | E26: 0 | F26: 0 | G26: 0 | H26: 0 | I26: 0 | J26: 0 | K26: 0 | L26: 21284 | M26: 11636 | N26: 14124 | O26: 14646 | P26: 14269 | Q26: 13981 | R26: 13037 | S26: 11995 | T26: 4541 | U26: 4425 | V26: 4121 | W26: 3753 | X26: 3035 | Y26: 2877 | Z26: 2076 | AA26: 1844.6747 | AB26: 1139.31 | AC26: 683.54 | AD26: 640.32505
B28: ORGANISMOS INTERNACIONALES | C28: 7279 | D28: 10944 | E28: 11627 | F28: 14862 | G28: 16257 | H28: 16795 | I28: 19167 | J28: 20311 | K28: 21757 | L28: 32357 | M28: 31376 | N28: 32115 | O28: 30601 | P28: 25260 | Q28: 15155 | R28: 15050 | S28: 14769 | T28: 16209 | U28: 16958 | V28: 17935 | W28: 18335 | X28: 19394 | Y28: 19857 | Z28: 19768 | AA28: 20230.498 | AB28: 21326.95 | AC28: 51037.44 | AD28: 68000.788
B30: ORGANISMOS OFICIALES | C30: 7380 | D30: 9698 | E30: 10870 | F30: 11904 | G30: 10063 | H30: 8311 | I30: 7634 | J30: 6258 | K30: 5017 | L30: 5876 | M30: 4935 | N30: 4428 | O30: 3389 | P30: 2952 | Q30: 1606 | R30: 1907 | S30: 1275 | T30: 1749 | U30: 1479 | V30: 1410 | W30: 849 | X30: 767 | Y30: 9026 | Z30: 9183 | AA30: 7844.7182 | AB30: 8280.38 | AC30: 6912.17 | AD30: 5398.0723
B32: BANCA COMERCIAL | C32: 21736 | D32: 1564 | E32: 1702 | F32: 1908 | G32: 2280 | H32: 2366 | I32: 3585 | J32: 3655 | K32: 2168 | L32: 715 | M32: 563 | N32: 527 | O32: 396 | P32: 294 | Q32: 859 | R32: 1165 | S32: 1453 | T32: 5102 | U32: 6055 | V32: 6586 | W32: 7273 | X32: 4702 | Y32: 4221 | Z32: 3126 | AA32: 1068.5919 | AB32: 2434.14 | AC32: 1194.16 | AD32: 2784.8972
B34: OTROS ACREEDORES | C34: 439 | D34: 505 | E34: 512 | F34: 989 | G34: 1053 | H34: 1445 | I34: 1385 | J34: 1587 | K34: 1913 | L34: 911 | M34: 264 | N34: 273 | O34: 242 | P34: 1436 | Q34: 1539 | R34: 2098 | S34: 2449 | T34: 2928 | U34: 1797 | V34: 1682 | W34: 1960 | X34: 2986 | Y34: 1541 | Z34: 2839 | AA34: 3431.1811 | AB34: 3101.41 | AC34: 2448.23 | AD34: 4019.7644
B36: ADELANTOS TRANSITORIOS BCRA | C36: 0 | D36: 0 | E36: 0 | F36: 0 | G36: 0 | H36: 0 | I36: 0 | J36: 0 | K36: 0 | L36: 0 | M36: 1079 | N36: 2526 | O36: 4468 | P36: 5263 | Q36: 5986 | R36: 6774 | S36: 7700 | T36: 9626 | U36: 11615 | V36: 15597 | W36: 25972 | X36: 28002 | Y36: 29402 | Z36: 25517 | AA36: 24115.153 | AB36: 25153.14 | AC36: 13296.82 | AD36: 14237.082
B38: III- ATRASOS PENDIENTE DE REESTRUCTURACIÓN | C38: 9232 | D38: 0 | E38: 0 | F38: 0 | G38: 0 | H38: 0 | I38: 0 | J38: 0 | K38: 0 | L38: 28 | M38: 11704.252 | N38: 28434.741 | O38: 46195.829 | P38: 5157.8648 | Q38: 6750.8946 | R38: 7271.2359 | S38: 8461.1905 | T38: 8678.4855 | U38: 9062.1741 | V38: 9265.5751 | W38: 9376.5018 | X38: 9440.1029 | Y38: 49 | Z38: 44 | AA38: 42.906828 | AB38: 107.43 | AC38: 104.84 | AD38: 103.95523
B40: IV- TOTAL DEUDA ELEGIBLE PENDIENTE DE REESTRUCTURACIÓN | C40: 0 | D40: 0 | E40: 0 | F40: 0 | G40: 0 | H40: 0 | I40: 0 | J40: 0 | K40: 0 | L40: 0 | M40: =+M42+M44+M46 -> 5 | N40: =+N42+N44+N46 -> 41 | O40: =+O42+O44+O46 -> 132 | P40: =+P42+P44+P46 -> 24011 | Q40: =+Q42+Q44+Q46 -> 27012 | R40: =+R42+R44+R46 -> 30360 | S40: =+S42+S44+S46 -> 31036 | T40: =+T42+T44+T46 -> 32531 | ... AD40: =+AD42+AD44+AD46 -> 2435.2095
B42: CAPITAL | M42: 0 | N42: 0 | O42: 0 | P42: 17966 | Q42: 19119 | R42: 20459 | S42: 19956 | T42: 20108 | U42: 6809 | V42: 6579 | W42: 6608 | X42: 6670 | Y42: 6352 | Z42: 6101 | AA42: 3613.9822 | AB42: 1258.4 | AC42: 1218.78 | AD42: 1058.0797
B44: MORA DE INTERÉS | M44: 0 | N44: 0 | O44: 0 | P44: 5591 | Q44: 6958 | R44: 8398 | S44: 9028 | T44: 9700 | U44: 4409 | V44: 4599 | W44: 4874 | X44: 5168 | Y44: 5280 | Z44: 5420 | AA44: 2510.2886 | AB44: 1022.69 | AC44: 1012.57 | AD44: 863.85757
B46: INTERESES COMPENSATORIOS (**) | M46: 5 | N46: 41 | O46: 132 | P46: 454 | Q46: 935 | R46: 1503 | S46: 2052 | T46: 2723 | U46: 3340 | V46: 3990 | W46: 4707 | X46: 5467 | Y46: 5945 | Z46: 6441 | AA46: 2343.8065 | AB46: 595.42 | AC46: 574.07 | AD46: 513.27222
B50: V- VALORES NEGOCIABLES VINCULADOS AL PBI (***) | C50: 0 | D50: 0 | E50: 0 | F50: 0 | G50: 0 | H50: 0 | I50: 0 | J50: 0 | K50: 0 | L50: 0 | M50: 0 | N50: 0 | O50: 0 | P50: 28784.426 | Q50: 29052.852 | R50: 28175.633 | S50: 19871.956 | T50: 18112.885 | U50: 22730.046 | V50: 19725.328 | W50: 15942.385 | X50: 15761.738 | Y50: 14430.352 | Z50: 13324.151 | AA50: 13001.694 | AB50: 13772.18 | AC50: 13192.94 | AD50: 12962.732
B52: (*) Los saldos de deuda al 31/12/92 se estimaron sobre la base de ajustar los registros obrante, retrotrayendo el efecto que sobre los saldos y la composición, produjera el Plan Brady.
B53: (**) Intereses compensatorios estimados, devengados e impagos con posterioridad a la fecha de vencimiento de cada título.
B54: (***) Valor remanente total. Es la diferencia entre el máximo a pagar de 48 unidades por cada 100 de valor nocional y la suma de los montos pagados hasta la actualidad, de acuerdo con las condiciones establecidas en las respectivas normas de emisión.

Sheet A.3.1
A1: Indice
B2: =+INDICE!B2 -> MINISTERIO DE ECONOMÍA
B3: =+A.2.4!B3 -> SECRETARÍA DE FINANZAS
B6: PERFIL DE VENCIMIENTOS DE CAPITAL E INTERÉS DE LA DEUDA BRUTA DE LA ADMINISTRACIÓN CENTRAL
B7: PERIODO PROYECTADO ENERO 2020 A DICIEMBRE 2020
B8: DEUDA EN SITUACIÓN DE PAGO NORMAL (1)
B10: (En miles de U$S - Tipo de cambio 31/12/2019)
C11: 2020 | O11: Total
C12: Enero | D12: Febrero | E12: Marzo | F12: Abril | G12: Mayo | H12: Junio | I12: Julio | J12: Agosto | K12: Septiembre | L12: Octubre | M12: Noviembre | N12: Diciembre | O12: 2020
B14: TÍTULOS PÚBLICOS | C14: =+SUM(C15:C16) -> 1167749.8 | D14: =+SUM(D15:D16) -> 1947290.6 | E14: =+SUM(E15:E16) -> 2258001.7 | F14: =+SUM(F15:F16) -> 6637122.6 | G14: =+SUM(G15:G16) -> 4278635.7 | H14: =+SUM(H15:H16) -> 4635967.9 | I14: =+SUM(I15:I16) -> 927689.7 | J14: =+SUM(J15:J16) -> 192356.84 | ... N14: =+SUM(N15:N16) -> 2428678.6 | O14: =+O15+O16 -> 32445397
B15: CAPITAL | C15: 87064.485 | D15: 1699554 | E15: 1437546.2 | F15: 5311737.3 | G15: 3508223.2 | H15: 2438891.9 | I15: 72848.292 | J15: 61815.034 | K15: 62001.047 | L15: 3433959.1 | M15: 2145848.1 | N15: 653532.63 | O15: =SUM(C15:N15) -> 20913021
B16: INTERÉS | C16: 1080685.3 | D16: 247736.58 | E16: 820455.48 | F16: 1325385.2 | G16: 770412.51 | H16: 2197076 | I16: 854841.41 | J16: 130541.8 | K16: 369295.62 | L16: 1278915.4 | M16: 681884.65 | N16: 1775146 | O16: =SUM(C16:N16) -> 11532376
B19: LETRAS DEL TESORO | C19: =+SUM(C20:C21) -> 749066.67 | D19: =+SUM(D20:D21) -> 1196033 | E19: =+SUM(E20:E21) -> 3686995.5 | F19: =+SUM(F20:F21) -> 2519760.6 | G19: =+SUM(G20:G21) -> 1984442.7 | H19: =+SUM(H20:H21) -> 2385898 | I19: =+SUM(I20:I21) -> 789910.07 | J19: =+SUM(J20:J21) -> 9350934.5 | ... N19: =+SUM(N20:N21) -> 243892.62 | O19: =+O20+O21 -> 24015479
B20: CAPITAL | C20: 692456.01 | D20: 1138990.2 | E20: 3594818.3 | F20: 2430121.1 | G20: 1940589.6 | H20: 1939561 | I20: 789910.07 | J20: 9350742.4 | K20: 185335.3 | L20: 923210.27 | M20: 0 | N20: 243892.62 | O20: =SUM(C20:N20) -> 23229627
B21: INTERÉS | C21: 56610.66 | D21: 57042.787 | E21: 92177.191 | F21: 89639.468 | G21: 43853.113 | H21: 446336.99 | I21: 0 | J21: 192.17708 | K21: 0 | L21: 0 | M21: 0 | N21: 0 | O21: =SUM(C21:N21) -> 785852.39
B24: ORGANISMOS INTERNACIONALES | C24: =+SUM(C25:C26) -> 150366.36 | D24: =+SUM(D25:D26) -> 559541.1 | E24: =+SUM(E25:E26) -> 382375.57 | F24: =+SUM(F25:F26) -> 164138.24 | G24: =+SUM(G25:G26) -> 627987.9 | H24: =+SUM(H25:H26) -> 222718.35 | I24: =+SUM(I25:I26) -> 146707.22 | J24: =+SUM(J25:J26) -> 575745.89 | ... N24: =+SUM(N25:N26) -> 216318.81 | O24: =+O25+O26 -> 4192467
