Workbook
Name _._IMPUESTOS_SOBRE_COMBUSTIBLES_Y_GAS_NATURAL: [1]C!$B$27:$N$27
Name _._IMPUESTOS_SOBRE_ENERGIA_ELECTRICA: [1]C!$B$28:$N$28
Name __r: #REF!
Name __r: #REF!
Name __r: #REF!
Name __r: #REF!
Name __r: #REF!
Name __r: #REF!
Name __r: #REF!
Name __r: #REF!
Name __r: #REF!
Name __r: #REF!
Name __r: #REF!
Name __r: #REF!
Name __r: #REF!
Name __r: #REF!
Name __r: #REF!
Name __r: #REF!
Name __r: #REF!
Name _r: #REF!
Name _r: #REF!
Name _r: #REF!
Name _r: #REF!
Name _r: #REF!
Name _r: #REF!
Name _r: #REF!
Name _r: #REF!
Name _r: #REF!
Name _r: #REF!
Name _r: #REF!
Name _r: #REF!
Name _r: #REF!
Name _r: #REF!
Name _r: #REF!
Name _r: #REF!
Name _r: #REF!
Name A_impresión_IM: '[2]03-08'!#REF!
Name ACC: '[3]CARTERA FONDO'!#REF!
Name ACP: '[3]CARTERA FONDO'!#REF!
Name AMPO5: "Gráfico 8"
Name AÑO: #REF!
Name AÑO: #REF!
Name año2003: #REF!
Name año2003: #REF!
Name cacho: [4]GRAFPROM!#REF!
Name cacho: [4]GRAFPROM!#REF!
Name cacho: [4]GRAFPROM!#REF!
Name carajo: #REF!
Name carajo: #REF!
Name CDF: '[3]CARTERA FONDO'!#REF!
Name CDF: '[3]CARTERA FONDO'!#REF!
Name CFA: '[3]CARTERA FONDO'!#REF!
Name CFD: '[3]CARTERA FONDO'!#REF!
Name CLH: '[3]CARTERA FONDO'!#REF!
Name Coef: [5]CoefStocks!$A$4:$AT$260
Name Coef: [5]CoefStocks!$A$4:$AT$260
Name Coef: [5]CoefStocks!$A$4:$AT$260
Name COPA: #N/A
Name COPARTICIPACION_FEDERAL__LEY_N__23548: [1]C!$B$13:$N$13
Name CUADRO_10.3.1: '[6]fondo promedio'!$A$36:$L$74

Sheet INDICE
B2: MINISTERIO DE ECONOMÍA
B3: SECRETARÍA DE FINANZAS
B5: DEUDA DE LA ADMINISTRACIÓN CENTRAL
B8: ÍNDICE
B10: HOJA | C10: CONTENIDO
B11: Deuda al 31/12/2021: nivel y composición
B12: A.1.1 | C12: Deuda de la Administración Central - Por instrumento y tipo de plazo
B13: A.1.2 | C13: Deuda Bruta de la Administración Central - Por Deuda Directa o Indirecta
B14: A.1.3 | C14: Deuda Bruta de la Administración Central - Por legislación, situación e instrumento
B15: A.1.4 | C15: Deuda Bruta de la Administración Central - Por tipo de moneda y tasa
B16: A.1.5 | C16: Tasa promedio ponderada por moneda e instrumento
B17: A.1.6 | C17: Vida promedio por instrumento
B18: A.1.7 | C18: Títulos públicos y letras del tesoro emitidos en moneda nacional
B19: A.1.8 | C19: Títulos públicos, letras del tesoro, pagarés y préstamos garantizados emitidos en moneda nacional y ajustables por CER
B20: A.1.9 | C20: Títulos públicos, letras del tesoro y pagarés emitidos en moneda extranjera
B21: A.1.10 | C21: Deuda elegible pendiente de reestructuración, desagregada por instrumento
B23: Evolución reciente de la deuda
B24: A.2.1 | C24: Deuda Bruta de la Administración Central - Serie de saldos trimestrales - 4to. Trimestre 2020/4to. Trimestre 2021
B25: A.2.2 | C25: Deuda Bruta de la Administración Central - Flujos y variaciones 4to. Trimestre 2021
B26: A.2.3 | C26: Deuda Bruta de la Administración Central - Flujos y variaciones acumulados 2021
B27: A.2.4 | C27: Serie de Tipos de Cambio y Coeficiente de Estabilización de Referencia (CER)
B28: A.2.5 | C28: Serie de la Deuda del Sector Público Nacional por año - 1992/2021
B30: Vencimientos de capital e interés de la deuda al 31-12-2021 proyectados
B31: A.3.1 | C31: Perfil mensual de vencimientos de capital e interés de la Deuda Bruta de la Administración Central - 01/2022 a 12/2022
B32: A.3.2 | C32: Perfil mensual de vencimientos de capital de la Deuda Bruta de la Administración Central, desagregado por instrumento - 2022
B33: A.3.3 | C33: Perfil mensual de vencimientos de interés de la Deuda Bruta de la Administración Central, desagregado por instrumento - 2022
B34: A.3.4 | C34: Perfil mensual de vencimientos de capital de la Deuda Bruta de la Administración Central, desagregado por instrumento - 2023
B35: A.3.5 | C35: Perfil mensual de vencimientos de interés de la Deuda Bruta de la Administración Central, desagregado por instrumento - 2023
B36: A.3.6 | C36: Perfil anual de vencimientos de capital e interés de la Deuda Bruta de la Administración Central
B37: A.3.7 | C37: Perfil anual de vencimientos de capital de la Deuda Bruta de la Administración Central, desagregado por instrumento
B38: A.3.8 | C38: Perfil anual de vencimientos de interés de la Deuda Bruta de la Administración Central, desagregado por instrumento
B40: Otros Cuadros
B41: A.4.1 | C41: Valores Negociables Vinculados al PBI
B42: A.4.2 | C42: Activos financieros de la Administración Central
B43: A.4.3 | C43: Activos financieros con cargo a provincias
B44: A.4.4 | C44: Flujos netos anuales con Organismos Internacionales
B45: A.4.5 | C45: Deuda Bruta de la Administración Central - Por residencia del tenedor
B46: A.4.6 | C46: Deuda Bruta Externa de la Administración Central - Perfil de vencimientos de capital
B47: A.4.7 | C47: Indicadores de sostenibilidad de la Deuda Bruta de la Administración Central

Sheet A.1.1
A1: Indice
B2: MINISTERIO DE ECONOMÍA
B3: SECRETARÍA DE FINANZAS
B6: DEUDA DE LA ADMINISTRACIÓN CENTRAL
B7: POR INSTRUMENTO Y POR TIPO DE PLAZO
B10: Datos al 31/12/2021
C11: Miles de u$s | D11: Miles de $
B13: I- DEUDA BRUTA + VALORES NEGOCIABLES VINCULADOS AL PBI (II + VI) | C13: =+C16+C84 -> 3.7621495e+08 | D13: =+D16+D84 -> 3.8656086e+10
B16: II- DEUDA BRUTA (III + IV + V) | C16: =+C19+C61+C66 -> 3.6323261e+08 | D16: =+D19+D61+D66 -> 3.7322151e+10
B19: III- DEUDA EN SITUACIÓN DE PAGO NORMAL | C19: =+C21+C54 -> 3.6068874e+08 | D19: =+D21+D54 -> 3.7060768e+10
B21: MEDIANO Y LARGO PLAZO | C21: =+C23+C27+C29+C52 -> 3.2576771e+08 | D21: =+D23+D27+D29+D52 -> 3.3472632e+10
B23: TÍTULOS PÚBLICOS | C23: =+C24+C25 -> 2.3036901e+08 | D23: =+D24+D25 -> 2.3670416e+10
B24: - Moneda nacional | C24: 60334299 | D24: 6.1993492e+09
B25: - Moneda extranjera | C25: 1.7003471e+08 | D25: 1.7471066e+10
B27: LETRAS DEL TESORO (1) | C27: 9432983.6 | D27: 9.6923906e+08
B29: PRÉSTAMOS | C29: =+C31+C33+C44+C46+C48+C50 -> 78101973 | D29: =+D31+D33+D44+D46+D48+D50 -> 8.0249777e+09
B31: PRÉSTAMOS GARANTIZADOS | C31: 751015.37 | D31: 77166829
B33: ORGANISMOS INTERNACIONALES | C33: =SUM(C34:C42) -> 68065416 | D33: =SUM(D34:D42) -> 6.9937215e+09
B34: - BCIE | C34: 79285.845 | D34: 8146620.6
B35: - BIRF | C35: 8517393 | D35: 8.7516213e+08
B36: - BID | C36: 14051577 | D36: 1.4437995e+09
B37: - FONPLATA | C37: 404331.3 | D37: 41545041
B38: - FIDA | C38: 33561.959 | D38: 3448491.3
B39: - CAF | C39: 3781438.9 | D39: 3.8854285e+08
B40: - OFID | C40: 123824.5 | D40: 12722967
B41: - FMI | C41: 40952110 | D41: 4.2078293e+09
B42: - BEI | C42: 121894.5 | D42: 12524660
B44: ORGANISMOS OFICIALES | C44: 4709868.6 | D44: 4.83939e+08
B46: BANCA COMERCIAL | C46: 2530002 | D46: 2.5995771e+08
B48: AVALES | C48: 1667070.6 | D48: 1.7129151e+08
... B52: ADELANTOS TRANSITORIOS BCRA | C52: 7863747 | D52: 808000000
B54: CORTO PLAZO (2) | C54: =SUM(C55:C59) -> 34921032 | D54: =SUM(D55:D59) -> 3.588136e+09
B56: ADELANTOS TRANSITORIOS BCRA | C56: 13285152 | D56: 1.3650493e+09
B57: LETRAS DEL TESORO | C57: 20687534 | D57: 2.1256442e+09
B58: AVALES | C58: 121095.08 | D58: 12442519
B59: PAGARES | C59: 827250.61 | D59: 85000000
B61: IV- DEUDA EN SITUACIÓN DE PAGO DIFERIDO (3) | C61: =+C63+C64 -> 104561.86 | D61: =+D63+D64 -> 10743731
B63: CAPITAL | C63: 96201.236 | D63: 9884677
B64: INTERÉS (4) | C64: 8360.6238 | D64: 859054.09
B66: V- DEUDA ELEGIBLE PENDIENTE DE REESTRUCTURACIÓN (5) | C66: =+C68+C73+C78 -> 2439303.2 | D66: =+D68+D73+D78 -> 2.506384e+08
...

Sheet A.1.2
A1: Indice
B2: MINISTERIO DE ECONOMÍA
B3: SECRETARÍA DE FINANZAS
B6: DEUDA BRUTA DE LA ADMINISTRACIÓN CENTRAL
B7: POR DEUDA DIRECTA E INDIRECTA
B10: Datos al 31/12/2021
C11: Miles de u$s
B13: I- DEUDA BRUTA (II + III) | C13: =+C16+C46 -> 3.6323261e+08
B16: II- DEUDA DIRECTA | C16: =+C18+C29+C35+C40 -> 3.5287356e+08
B18: LARGO PLAZO | C18: =SUM(C20:C27) -> 3.1552975e+08
B20: Títulos Públicos | C20: 2.3036901e+08
B21: Préstamos Garantizados | C21: 751015.37
B22: Organismos Intenacionales | C22: 66162458
B23: Organismos Oficiales | C23: 4603546.1
B24: Banca Comercial | C24: 2378790
B25: Adelantos Transitorios | C25: 7863747
B26: Letras del Tesoro | C26: 3022590
B27: Pagarés del Tesoro | C27: 378599.56
B29: CORTO PLAZO (1) | C29: =SUM(C31:C33) -> 34799937
B31: Adelantos Transitorios | C31: 13285152
B32: Letras del Tesoro | C32: 20687534
B33: Pagarés del Tesoro | C33: 827250.61
B35: DEUDA EN SITUACIÓN DE PAGO DIFERIDO (2) | C35: =+C37+C38 -> 104561.86
B37: Capital | C37: 96201.236
B38: Interés (3) | C38: 8360.6238
B40: DEUDA ELEGIBLE PENDIENTE DE REESTRUCTURACIÓN (4) | C40: =+C42+C43+C44 -> 2439303.2
B42: Capital | C42: 1059021
B43: Atrasos de Interés | C43: 865683.32
B44: Intereses compensatorios (5) | C44: 514598.8
B46: III- DEUDA INDIRECTA | C46: =SUM(C48:C51) -> 10359053
B48: Avales | C48: 1788165.7
B49: Garantías a las provincias | C49: 2160493.4
B50: Letras en garantía | C50: 6410393.5
B53: (1) Incluye operaciones de hasta un año de plazo.
B54: (2) Deuda en situacion de pago diferido, no elegible para canjes de Dtos. 1735/04 y 563/10.
B55: (3) No incluye intereses moratorios ni punitorios.
B56: (4) Se trata de la deuda elegible y no presentada al canje (Dtos. 1735/04 y 563/10) y no cancelada a la fecha en el marco de los acuerdos contemplados en la Ley n° 27.249.
B57: (5) Intereses compensatorios estimados, devengados e impagos con posterioridad a la fecha de vencimiento de cada título.

Sheet A.1.3
A1: Indice
B2: MINISTERIO DE ECONOMÍA
B3: SECRETARÍA DE FINANZAS
B6: DEUDA BRUTA DE LA ADMINISTRACIÓN CENTRAL
B7: POR LEGISLACIÓN, INSTRUMENTO Y SITUACIÓN
B10: Datos al 31/12/2021
C11: Saldo Bruto | D11: %
C12: Miles de u$s
B14: DEUDA BRUTA + VALORES NEGOCIABLES VINCULADOS AL PBI | C14: =+C17+C64 -> 3.7621495e+08
B17: - DEUDA BRUTA | C17: =+C19+C21+C23 -> 3.6323261e+08 | D17: =+D19+D21+D23 -> 1
B19: - EN SITUACIÓN DE PAGO NORMAL | C19: =+C28+C48 -> 3.6068874e+08 | D19: =+C19/$C$17 -> 0.9929966
B21: - EN SITUACIÓN DE PAGO DIFERIDO (1) | C21: =+C36+C54 -> 104561.86 | D21: =+C21/$C$17 -> 0.00028786474
B23: - ELEGIBLE PENDIENTE DE REESTRUCTURACIÓN (2) | C23: =+C41+C58 -> 2439303.2 | D23: =+C23/$C$17 -> 0.0067155401
B26: I- LEGISLACIÓN ARGENTINA | C26: =+C28+C36+C41 -> 2.1870022e+08 | D26: =+D28+D36+D41 -> 0.60209412
B28: - EN SITUACIÓN DE PAGO NORMAL | C28: =SUM(C29:C34) -> 2.1858068e+08 | D28: =+C28/$C$17 -> 0.60176503
B29: TÍTULOS PÚBLICOS Y LETRAS DEL TESORO | C29: 1.9159429e+08 | D29: =+C29/$C$17 -> 0.52746997
B30: PRÉSTAMOS GARANTIZADOS | C30: 751015.37 | D30: =+C30/$C$17 -> 0.002067588
B31: ADELANTOS TRANSITORIOS BCRA | C31: 21148899 | D31: =+C31/$C$17 -> 0.058224119
B32: AVALES | C32: 1788165.7 | D32: =+C32/$C$17 -> 0.0049229218
B33: BANCA COMERCIAL | C33: 2092457.4 | D33: =+C33/$C$17 -> 0.0057606541
B34: PAGARÉS DEL TESORO | C34: 1205850.2 | D34: =+C34/$C$17 -> 0.003319774
B36: - EN SITUACIÓN DE PAGO DIFERIDO (1) | C36: =+SUM(C37:C39) -> 62298.482 | D36: =+C36/$C$17 -> 0.00017151126
B37: BANCA COMERCIAL | C37: 172.73352 | D37: =+C37/$C$17 -> 4.7554519e-07
B38: AVALES | C38: 60464.16 | D38: =+C38/$C$17 -> 0.00016646127
B39: OTROS | C39: 1661.5893 | D39: =+C39/$C$17 -> 4.5744496e-06
B41: - ELEGIBLE PENDIENTE DE REESTRUCTURACIÓN (2) | C41: =SUM(C42:C44) -> 57237.907 | D41: =+C41/$C$17 -> 0.00015757921
B42: CAPITAL | C42: 48187.361 | D42: =+C42/$C$17 -> 0.00013266254
B43: ATRASOS DE INTERÉS | C43: 2306.2045 | D43: =+C43/$C$17 -> 6.3491121e-06
B44: INTERESES COMPENSATORIOS (3) | C44: 6744.3415 | D44: =+C44/$C$17 -> 1.8567555e-05
B46: II- LEGISLACIÓN EXTRANJERA | C46: =+C48+C54+C58 -> 1.4453239e+08 | D46: =+D48+D54+D58 -> 0.39790588
B48: - EN SITUACIÓN DE PAGO NORMAL | C48: =SUM(C49:C52) -> 1.4210806e+08 | D48: =+C48/$C$17 -> 0.39123157
B49: TÍTULOS PÚBLICOS Y LETRAS DEL TESORO | C49: 68895234 | D49: =+C49/$C$17 -> 0.18967249
B50: ORGANISMOS INTERNACIONALES | C50: 68065416 | D50: =+C50/$C$17 -> 0.18738796
B51: ORGANISMOS OFICIALES | C51: 4709868.6 | D51: =+C51/$C$17 -> 0.012966536
B52: BANCA COMERCIAL | C52: 437544.62 | D52: =+C52/$C$17 -> 0.0012045852
B54: - EN SITUACIÓN DE PAGO DIFERIDO (1) | C54: =SUM(C55:C56) -> 42263.377 | D54: =+C54/$C$17 -> 0.00011635348
B55: BANCA COMERCIAL | C55: 33578.545 | D55: =+C55/$C$17 -> 9.2443641e-05
B56: OTROS | C56: 8684.8322 | D56: =+C56/$C$17 -> 2.3909836e-05
B58: - ELEGIBLE PENDIENTE DE REESTRUCTURACIÓN (2) | C58: =SUM(C59:C61) -> 2382065.3 | D58: =+C58/$C$17 -> 0.0065579609
B59: CAPITAL | C59: 1010833.7 | D59: =+C59/$C$17 -> 0.0027828825
...

Sheet A.1.4
A1: Indice
B2: MINISTERIO DE ECONOMÍA
B3: SECRETARÍA DE FINANZAS
B6: DEUDA BRUTA DE LA ADMINISTRACIÓN CENTRAL
B7: POR MONEDA Y TASA
C10: AL 31/12/2021
C11: Deuda Bruta de la Administración Central (Excluida la elegible pendiente de reestructuración) | E11: Deuda elegible pendiente de reestructuración | G11: Total Deuda Bruta
C13: Miles de u$s | D13: % | E13: Miles de u$s | F13: % | G13: Miles de u$s | H13: %
B15: TOTAL | C15: =+C17+C28 -> 3.6079331e+08 | D15: =+D17+D28 -> 0.99328446 | E15: =+E17+E28 -> 2439303.2 | F15: =+F17+F28 -> 0.0067155401 | G15: =+G17+G28 -> 3.6323261e+08 | H15: =+H17+H28 -> 1
B17: Moneda local (1) | C17: =+C19+C24 -> 1.0780948e+08 | D17: =+D19+D24 -> 0.29680562 | E17: =+E19+E24 -> 56367.796 | F17: =+F19+F24 -> 0.00015518374 | G17: =+G19+G24 -> 1.0786585e+08 | H17: =+H19+H24 -> 0.2969608
B19: Deuda no ajustable por CER | C19: =SUM(C20:C22) -> 45604684 | D19: =SUM(D20:D22) -> 0.12555229 | E19: =SUM(E20:E22) -> 307.62682 | F19: =SUM(F20:F22) -> 8.469141e-07 | G19: =SUM(G20:G22) -> 45604992 | H19: =SUM(H20:H22) -> 0.12555313
B20: Tasa fija | C20: 11432824 | D20: =+C20/$G$15 -> 0.031475213 | E20: 8.7822256 | F20: =+E20/$G$15 -> 2.4177966e-08 | G20: =+C20+E20 -> 11432833 | H20: =+F20+D20 -> 0.031475237
B21: Tasa Cero | C21: 32020353 | D21: =+C21/$G$15 -> 0.088153851 | E21: 0 | F21: =+E21/$G$15 -> 0 | G21: =+C21+E21 -> 32020353 | H21: =+F21+D21 -> 0.088153851
B22: Tasas Variables | C22: 2151507.3 | D22: =+C22/$G$15 -> 0.0059232217 | E22: 298.84459 | F22: =+E22/$G$15 -> 8.2273614e-07 | G22: =+C22+E22 -> 2151806.1 | H22: =+F22+D22 -> 0.0059240444
B24: Deuda ajustable por CER | C24: =SUM(C25:C26) -> 62204794 | D24: =SUM(D25:D26) -> 0.17125333 | E24: =SUM(E25:E26) -> 56060.169 | F24: =SUM(F25:F26) -> 0.00015433683 | G24: =SUM(G25:G26) -> 62260854 | H24: =SUM(H25:H26) -> 0.17140767
B25: Tasa fija | C25: 48569033 | D25: =+C25/$G$15 -> 0.13371331 | E25: 46516.861 | F25: =+E25/$G$15 -> 0.00012806356 | G25: =+C25+E25 -> 48615550 | H25: =+F25+D25 -> 0.13384137
B26: Tasa cero | C26: 13635761 | D26: =+C26/$G$15 -> 0.037540024 | E26: 9543.3076 | F26: =+E26/$G$15 -> 2.6273268e-05 | G26: =+C26+E26 -> 13645304 | H26: =+F26+D26 -> 0.037566297
B28: Moneda extranjera | C28: =+C30+C37+C47+C50+C44 -> 2.5298383e+08 | D28: =+D30+D37+D47+D50+D44 -> 0.69647884 | E28: =+E30+E37+E47+E50+E44 -> 2382935.4 | F28: =+F30+F37+F47+F50+F44 -> 0.0065603564 | G28: =+G30+G37+G47+G50+G44 -> 2.5536676e+08 | H28: =+H30+H37+H47+H50+H44 -> 0.7030392
B30: Deuda en dólares estadounidenses | C30: =SUM(C31:C33) -> 2.0440555e+08 | D30: =SUM(D31:D33) -> 0.56274009 | E30: =SUM(E31:E33) -> 1467106.6 | F30: =SUM(F31:F33) -> 0.0040390278 | G30: =SUM(G31:G33) -> 2.0587266e+08 | H30: =SUM(H31:H33) -> 0.56677911
B31: Tasa fija | C31: 1.1408708e+08 | D31: =+C31/$G$15 -> 0.3140882 | E31: 1379175.2 | F31: =+E31/$G$15 -> 0.0037969476 | G31: =+C31+E31 -> 1.1546625e+08 | H31: =+F31+D31 -> 0.31788515
B32: Tasa Cero | C32: 9459313.5 | D32: =+C32/$G$15 -> 0.026042027 | E32: 63 | F32: =+E32/$G$15 -> 1.7344258e-07 | G32: =+C32+E32 -> 9459376.5 | H32: =+F32+D32 -> 0.026042201
B33: Tasas Variables | C33: =+C34+C35 -> 80859159 | D33: =+D34+D35 -> 0.22260986 | E33: =+E34+E35 -> 87868.416 | F33: =+F34+F35 -> 0.00024190674 | G33: =+C33+E33 -> 80947028 | H33: =+H34+H35 -> 0.22285176
B34: Tasa Libo | C34: 23265131 | D34: =+C34/$G$15 -> 0.064050227 | E34: 80677.426 | F34: =+E34/$G$15 -> 0.00022210954 | G34: =+C34+E34 -> 23345808 | H34: =+F34+D34 -> 0.064272336
B35: Otras tasas variables | C35: 57594028 | D35: =+C35/$G$15 -> 0.15855963 | E35: 7190.9894 | F35: =+E35/$G$15 -> 1.9797202e-05 | G35: =+C35+E35 -> 57601219 | H35: =+F35+D35 -> 0.15857943
B37: Deuda en Euros | C37: =SUM(C38:C40) -> 6741175.2 | D37: =SUM(D38:D40) -> 0.018558838 | E37: =SUM(E38:E40) -> 868087.84 | F37: =SUM(F38:F40) -> 0.0023898951 | G37: =SUM(G38:G40) -> 7609263 | H37: =SUM(H38:H40) -> 0.020948733
B38: Tasa fija | C38: 6417180.6 | D38: =+C38/$G$15 -> 0.017666863 | E38: 852805.15 | F38: =+E38/$G$15 -> 0.002347821 | G38: =+C38+E38 -> 7269985.8 | H38: =+F38+D38 -> 0.020014684
B39: Tasa Cero | C39: 0 | D39: =+C39/$G$15 -> 0 | E39: 0 | F39: =+E39/$G$15 -> 0 | G39: =+C39+E39 -> 0 | H39: =+F39+D39 -> 0
B40: Tasas Variables | C40: =+C41+C42 -> 323994.58 | D40: =+D41+D42 -> 0.00089197548 | E40: =+E41+E42 -> 15282.684 | F40: =+F41+F42 -> 4.2074096e-05 | G40: =+C40+E40 -> 339277.26 | H40: =+H41+H42 -> 0.00093404957
B41: Tasa Libo | C41: 323994.58 | D41: =+C41/$G$15 -> 0.00089197548 | E41: 15282.684 | F41: =+E41/$G$15 -> 4.2074096e-05 | G41: =+C41+E41 -> 339277.26 | H41: =+F41+D41 -> 0.00093404957
B42: Otras tasas variables | C42: 0 | D42: =+C42/$G$15 -> 0 | E42: 0 | F42: =+E42/$G$15 -> 0 | G42: =+C42+E42 -> 0 | H42: =+F42+D42 -> 0
B44: Deuda en Derechos especiales de giro | C44: =+C45 -> 40959532 | D44: =+SUM(D45:D46) -> 0.11276392 | E44: =+SUM(E45:E46) -> 0 | F44: =+SUM(F45:F46) -> 0 | G44: =+SUM(G45:G46) -> 40959532 | H44: =+SUM(H45:H46) -> 0.11276392
B45: Tasas Variables | C45: 40959532 | D45: =+C45/$G$15 -> 0.11276392 | E45: 0 | F45: =+E45/$G$15 -> 0 | G45: =+C45+E45 -> 40959532 | H45: =+F45+D45 -> 0.11276392
B47: Deuda en Yenes | C47: =+SUM(C48:C48) -> 646850.79 | D47: =+SUM(D48:D48) -> 0.0017808169 | E47: =+SUM(E48:E48) -> 27848.314 | F47: =+SUM(F48:F48) -> 7.6667989e-05 | G47: =+SUM(G48:G48) -> 674699.1 | H47: =+SUM(H48:H48) -> 0.0018574849
B48: Tasa fija | C48: 646850.79 | D48: =+C48/$G$15 -> 0.0017808169 | E48: 27848.314 | F48: =+E48/$G$15 -> 7.6667989e-05 | G48: =+C48+E48 -> 674699.1 | H48: =+F48+D48 -> 0.0018574849
B50: Deuda en otras monedas extranjeras (2) | C50: =SUM(C51:C52) -> 230720.58 | D50: =SUM(D51:D52) -> 0.00063518687 | E50: =SUM(E51:E52) -> 19892.615 | F50: =SUM(F51:F52) -> 5.4765499e-05 | G50: =SUM(G51:G52) -> 250613.2 | H50: =SUM(H51:H52) -> 0.00068995236
B51: Tasa fija | C51: 227212.59 | D51: =+C51/$G$15 -> 0.00062552915 | E51: 19892.615 | F51: =+E51/$G$15 -> 5.4765499e-05 | G51: =+C51+E51 -> 247105.2 | H51: =+F51+D51 -> 0.00068029465
B52: Tasa Cero | C52: 3507.9967 | D52: =+C52/$G$15 -> 9.657714e-06 | E52: 0 | G52: =+C52+E52 -> 3507.9967 | H52: =+F52+D52 -> 9.657714e-06
B55: (1) La deuda emitida en dólares, pero cuyo pago de capital e interés es en pesos, se clasifica como deuda en Moneda Local.
B56: (2) Incluye: Libras esterlinas, Franco Suizo, Corona Danesa, Corona Sueca, Dólar Canadiense, Dinar Kuwaiti, Dólar Australiano y Dirham de Emiratos Árabes Unidos.

Sheet A.1.5
A1: Indice
B2: MINISTERIO DE ECONOMÍA
B3: SECRETARÍA DE FINANZAS
B6: TASA PROMEDIO PONDERADA (1)
B7: POR MONEDA E INSTRUMENTO
B10: Datos al 31/12/2021
B11: TASA PROMEDIO PONDERADA TOTAL | C11: 0.027491311
B13: Deuda en pesos no ajustables por CER | C13: 0.1263699
B15: Títulos Públicos | C15: 0.23275718
B16: Letras del Tesoro | C16: 0.4097057
B17: Otros préstamos | C17: 0.010337207
B18: Adelantos Transitorios BCRA | C18: 0
B20: Deuda en pesos ajustables por CER | C20: 0.022150716
B22: Títulos Públicos | C22: 0.023690148
B23: Letras del Tesoro | C23: 0.015385005
B24: Préstamos garantizados | C24: 0.05
B25: Otros préstamos | C25: 0.0177
B27: Deuda en dólares estadounidenses | C27: 0.0097681731
... B55: Otros préstamos | C55: 0.0025312926
B58: (1) Nota Metodológica: Cálculo realizado sobre la deuda en situación de pago normal. Se aplican las tasas de referencia vigentes al 31/12/2021, incluyendo la tasa "plena" en aquellos instrumentos que capitalizan parte de los intereses que devengan.

Sheet A.1.6
A1: Indice
B2: MINISTERIO DE ECONOMÍA
B3: SECRETARÍA DE FINANZAS
B6: VIDA PROMEDIO (1)
B7: POR INSTRUMENTO
B10: Datos al 31/12/2021 | C10: - En años -
B12: VIDA PROMEDIO TOTAL | C12: 6.139862
B14: Títulos Públicos | C14: 7.5259365
B16: Letras en Garantía | C16: 9.6494218
B18: Letras del Tesoro | C18: 1.022718
B20: Total Préstamos | C20: 4.666415
B22: - Organismos Internacionales | C22: 4.774985
B24: - Organismos Oficiales | C24: 3.5266285
B26: - Préstamos Garantizados (Canje Noviembre 2001) | C26: 9.1349647
B28: - Pagarés del Tesoro | C28: 4.7519294
B30: - Banca Comercial | C30: 1.504075
B32: - Avales | C32: 6.0757054
B34: Adelantos Transitorios | C34: 1.2222683
B37: (1) Nota Metodológica: Cálculo realizado sobre la deuda en situación de pago normal.

Sheet A.1.7
A1: Indice
B2: MINISTERIO DE ECONOMÍA
B3: SECRETARÍA DE FINANZAS
B6: TÍTULOS PÚBLICOS Y LETRAS DEL TESORO
B7: EMITIDOS EN MONEDA NACIONAL
B8: DATOS AL 31/12/2021
H11: En miles de u$s
B12: Fecha de emisión | C12: Denominación | D12: Tasa vigente | E12: Vencimiento | F12: Valor nominal original en circulación | G12: Valor nominal residual en circulación (1) | H12: Valor nominal actualizado en circulación (2)
C18: TÍTULOS PÚBLICOS | F18: =+F20+F23+F40 -> 13099058 | G18: =+G20+G23+G40 -> 12844151 | H18: =+H20+H23+H40 -> 12896542
C20: BONOS DE CONSOLIDACIÓN | F20: =+F21 -> 204171.41 | G20: =+G21 -> 69418.279 | H20: =+H21 -> 121807.7
B21: 40182 | C21: PR15/$/BADLAR/04-10-2022 | D21: Badlar Bancos Privados | E21: 2022 | F21: 204171.41 | G21: 69418.279 | H21: 121807.7
C23: BONOS | F23: =+SUM(F24:F38) -> 12894887 | G23: =+SUM(G24:G38) -> 12774733 | H23: =+SUM(H24:H38) -> 12774733
B24: 43294 | C24: BONAR/DLK/4,50%U$S-2,35%$/13-02-2020 (3) | D24: 4,50% U$S | E24: 2022 | F24: 739.069 | G24: 739.069 | H24: 739.069
B25: 43193 | C25: BONAR/$/6,72763943919512%/31-12-2028 | D25: 0.067276394 | E25: 2028 | F25: 456295.89 | G25: 340044.6 | H25: 340044.6
B26: 42828 | C26: BONAR/$/BADLAR+200PB/03-04-2022 | D26: Badlar Bancos Privados + 2,00% | E26: 2022 | F26: 675524.8 | G26: 675524.8 | H26: 675524.8
B27: 32875 | C27: BONO CONSOLIDADO/$/02-01-2089 | D27: Tasa Cero | E27: 2089 | F27: 8578.722 | G27: 7549.2754 | H27: 7549.2754
B28: 42660 | C28: BONTE/$/15,50%/17-10-2026 | D28: 0.155 | E28: 2026 | F28: 939851.23 | G28: 939851.23 | H28: 939851.23
B29: 42660 | C29: BONTE/$/16,00%/17-10-2023 | D29: 0.16 | E29: 2023 | F29: 624334.34 | G29: 624334.34 | H29: 624334.34
B30: 43866 | C30: BONTE/DLK/4,00%/05-08-2021 (3) | D30: 0.04 | E30: 2022 | F30: 4.84 | G30: 4.84 | H30: 4.84
B31: 44133 | C31: BONTE/DLK/0,10%/29-04-2022 (3) | D31: 0.001 | E31: 2022 | F31: 1952375 | G31: 1952375 | H31: 1952375
B32: 43972 | C32: BONTE/$/22,00%/21-05-2022 | D32: 0.22 | E32: 2022 | F32: 3595049.4 | G32: 3595049.4 | H32: 3595049.4
B33: 44232 | C33: BONTE/$/BADLAR+525PB/06-02-2023 | D33: Badlar Bancos Privados + 5,25% | E33: 2023 | F33: 565750.26 | G33: 565750.26 | H33: 565750.26
B34: 44337 | C34: BONTE/DLK/0,20%/30-11-2022 (3) | D34: 0.002 | E34: 2022 | F34: 1613635.6 | G34: 1613635.6 | H34: 1613635.6
B35: 44382 | C35: BONTE/$/BADLAR/05-07-2030 | D35: Badlar Bancos Privados | E35: 2030 | F35: 78788.665 | G35: 78788.665 | H35: 78788.665
B36: 44425 | C36: BONTE/$/BADLAR+400PB/17-08-2031 | D36: Badlar Bancos Privados + 4,00% | E36: 2031 | F36: 114908.35 | G36: 112035.64 | H36: 112035.64
B37: 44452 | C37: BONTE/DLK/0,30%/28-04-2023 (3) | D37: 0.003 | E37: 2023 | F37: 2221751.6 | G37: 2221751.6 | H37: 2221751.6
B38: 44552 | C38: BONTE /$/ BADLAR/22-12-2026 | D38: Badlar Bancos Privados | E38: 2026 | F38: 47298.711 | G38: 47298.711 | H38: 47298.711
C40: AMPAROS Y EXCEPCIONES | H40: 1.4664214
C42: LETRAS DEL TESORO | F42: =+SUM(F43:F54) -> 8266750.2 | G42: =+SUM(G43:G54) -> 8266748.2 | H42: =+SUM(H43:H54) -> 8266748.2
B43: 44095 | C43: LETRA/DLK/CMEA/21-09-2022 (3) | D43: Tasa Cero | E43: 2022 | F43: 124646.08 | G43: 124646.08 | H43: 124646.08
B44: 44399 | C44: LETES/$/31-01-2022 | D44: Tasa Cero | E44: 2022 | F44: 2075544.3 | G44: 2075544.3 | H44: 2075544.3
B45: 44469 | C45: LETES/$/28-02-2022 | D45: Tasa Cero | E45: 2022 | F45: 1307245.2 | G45: 1307245.2 | H45: 1307245.2
B46: 44498 | C46: LETES/$/31-03-2022 | D46: Tasa Cero | E46: 2022 | F46: 1319530.3 | G46: 1319530.3 | H46: 1319530.3
B47: 44530 | C47: LETES/$/29-04-2022 | D47: Tasa Cero | E47: 2022 | F47: 488597.7 | G47: 488597.7 | H47: 488597.7
B48: 44545 | C48: LELITE/30 DIAS/$/14-01-2022 | D48: Tasa Cero | E48: 2022 | F48: 210024.33 | G48: 210024.33 | H48: 210024.33
B49: 44545 | C49: LETES/$/31-05-2022 | D49: Tasa Cero | E49: 2022 | F49: 103858.64 | G49: 103858.64 | H49: 103858.64
B50: 44384 | C50: LETRA/$/INTRA SP/03-01-2022 | D50: Tasa Badlar Pública | E50: 2022 | F50: 235247 | G50: 235247 | H50: 235247
B51: 44473 | C51: LETRA/$/INTRA SP/01-04-2022 | D51: Tasa Badlar Pública | E51: 2022 | F51: 315053.03 | G51: 315053.03 | H51: 315053.03
B52: 43608 | C52: LELINKS/DLK/4,25%/04-12-2019 (3) | D52: 0.0425 | E52: 2022 | F52: 4.857 | G52: 2.9142 | H52: 2.9142
B53: 44377 | C53: LETES/$/31-12-2021 | D53: Tasa Cero | E53: 2021 | F53: 2077779.8 | G53: 2077779.8 | H53: 2077779.8
...

Sheet A.1.8
A1: Indice
B2: MINISTERIO DE ECONOMÍA
B3: SECRETARÍA DE FINANZAS
B6: TÍTULOS PÚBLICOS, LETRAS DEL TESORO, PRÉSTAMOS GARANTIZADOS Y PAGARÉS
B7: EMITIDOS EN MONEDA NACIONAL AJUSTABLES POR CER
B8: DATOS AL 31/12/2021
H11: En miles de u$s
B12: Fecha de emisión | C12: Denominación | D12: Tasa Vigente | E12: Vencimiento | F12: Valor nominal original en circulación (1) | G12: Valor nominal residual en circulación (2) | H12: Valor nominal actualizado en circulación (3)
C17: TÍTULOS PÚBLICOS | F17: =+F22+F19+F35+F42 -> 18503479 | G17: =+G22+G19+G35+G42 -> 18488958 | H17: =+H22+H19+H35+H42 -> 47437757
C19: BONOS DE CONSOLIDACIÓN | F19: =+F20 -> 18811.97 | G19: =+G20 -> 4291.0103 | H19: =+H20 -> 138012.37
B20: 38061 | C20: PR13/$+CER/2,00%/15-03-2024 | D20: 0.02 | E20: 2024 | F20: 18811.97 | G20: 4291.0103 | H20: 138012.37
C22: BONOS | F22: =+SUM(F23:F33) -> 18126131 | G22: =+SUM(G23:G33) -> 18126131 | H22: =+SUM(H23:H33) -> 34701204
B23: 43165 | C23: BONCER/$+CER/4,00%/06-03-2023 | D23: 0.04 | E23: 2023 | F23: 275352.68 | G23: 275352.68 | H23: 1207485.6
B24: 43217 | C24: BONCER/$+CER/4,00%/27-04-2025 | D24: 0.04 | E24: 2025 | F24: 283190.25 | G24: 283190.25 | H24: 1194791.9
B25: 43908 | C25: BONCER/$+CER/1,20%/18-03-2022 | D25: 0.012 | E25: 2022 | F25: 2558863.4 | G25: 2558863.4 | H25: 4874251.9
B26: 43915 | C26: BONCER/$+CER/1,40%/25-03-2023 | D26: 0.014 | E26: 2023 | F26: 2997791.9 | G26: 2997791.9 | H26: 5684871.4
B27: 43915 | C27: BONCER/$+CER/1,50%/25-03-2024 | D27: 0.015 | E27: 2024 | F27: 3365285 | G27: 3365285 | H27: 6381768.2
B28: 43433 | C28: BONCER/$+CER/8,50%/29-11-2022 | D28: 0.085 | E28: 2022 | F28: 330552.51 | G28: 330552.51 | H28: 1082102.9
B29: 43971 | C29: BONCER/$+CER/1,30%/20-09-2022 | D29: 0.013 | E29: 2022 | F29: 3566194.1 | G29: 3566194.1 | H29: 6443992.6
B30: 44056 | C30: BONCER/$+CER//1,45%/13-08-2023 | D30: 0.0145 | E30: 2023 | F30: 2934639.6 | G30: 2934639.6 | H30: 5055604.7
B31: 44078 | C31: BONCER/$+CER/2%/09-11-2026 | D31: 0.02 | E31: 2026 | F31: 651003.01 | G31: 651003.01 | H31: 1106416.3
B32: 44078 | C32: BONCER/$+CER/2,25%/09-11-2028 | D32: 0.0225 | E32: 2028 | F32: 89993.209 | G32: 89993.209 | H32: 152948.54
B33: 44253 | C33: BONCER/$+CER/1,55%/26-07-2024 | D33: 0.0155 | E33: 2024 | F33: 1073265.3 | G33: 1073265.3 | H33: 1516970
C35: BONOS DE LA REESTRUCTURACIÓN - DTO. 1735/04 y 563/10 | F35: =SUM(F36:F40) -> 358536.27 | G35: =SUM(G36:G40) -> 358536.27 | H35: =SUM(H36:H40) -> 12597355
B36: 37986 | C36: PAR/$+CER/TASA FIJA/31-12-2038/DTO. 1735-04 | D36: 0.0177 | E36: 2038 | F36: 27519.58 | G36: 27519.58 | H36: 729960.16
B37: 37986 | C37: PAR/$+CER/TASA FIJA/31-12-2038/DTO. 563-10 | D37: 0.0177 | E37: 2038 | F37: 109.44543 | G37: 109.44543 | H37: 2903.0532
B38: 37986 | C38: DISCOUNT/$+CER/5,83%/31-12-2033/DTO. 1735-04 | D38: 0.0583 | E38: 2033 | F38: 101617.11 | G38: 101617.11 | H38: 3422993.9
B39: 37986 | C39: DISCOUNT/$+CER/5,83%/31-12-2033/DTO. 563-10 | D39: 0.0583 | E39: 2033 | F39: 1221.5135 | G39: 1221.5135 | H39: 41146.923
B40: 37986 | C40: CUASIPAR/$+CER/3,31%/31-12-2045/DTO. 1735-04 | D40: 0.0331 | E40: 2045 | F40: 228068.62 | G40: 228068.62 | H40: 8400350.8
C42: AMPAROS Y EXCEPCIONES | H42: 1185.6692
C44: LETRAS DEL TESORO | F44: =+SUM(F45:F52) -> 10872357 | G44: =+SUM(G45:G52) -> 10872357 | H44: =+SUM(H45:H52) -> 13635761
B45: 44273 | C45: LETES/$+CER/28-02-2022 | D45: Tasa Cero | E45: 2022 | F45: 1926290 | G45: 1926290 | H45: 2649499.5
B46: 44286 | C46: LETES/$+CER/31-03-2022 | D46: Tasa Cero | E46: 2022 | F46: 1100979.3 | G46: 1100979.3 | H46: 1492037.7
B47: 44305 | C47: LETES/$+CER/18-04-2022 | D47: Tasa Cero | E47: 2022 | F47: 1339148.5 | G47: 1339148.5 | H47: 1772889.6
B48: 44337 | C48: LETES/$+CER/23-05-2022 | D48: Tasa Cero | E48: 2022 | F48: 1733516.7 | G48: 1733516.7 | H48: 2186540.4
B49: 44377 | C49: LETES/$+CER/30-06-2022 | D49: Tasa Cero | E49: 2022 | F49: 2146315.9 | G49: 2146315.9 | H49: 2578693.8
B50: 44413 | C50: LETES/$+CER/29-07-2022 | D50: Tasa Cero | E50: 2022 | F50: 1479318.7 | G50: 1479318.7 | H50: 1711790.5
B51: 44530 | C51: LETES/$+CER/16-08-2022 | D51: Tasa Cero | E51: 2022 | F51: 780450.96 | G51: 780450.96 | H51: 804173.27
B52: 44377 | C52: LETES/$+CER/31-12-2021 | D52: Tasa Cero | E52: 2021 | F52: 366337.09 | G52: 366337.09 | H52: 440136.14
C54: PRÉSTAMOS GARANTIZADOS | F54: =SUM(F55:F62) -> 16339.094 | G54: =SUM(G55:G62) -> 16339.094 | H54: =SUM(H55:H62) -> 751015.37
...

Sheet A.1.9
A1: Indice
B2: MINISTERIO DE ECONOMÍA
B3: SECRETARÍA DE FINANZAS
B6: TÍTULOS PÚBLICOS, LETRAS DEL TESORO Y PAGARÉS
B7: EMITIDOS EN MONEDA EXTRANJERA
B8: DATOS AL 31/12/2021
H11: En miles de u$s
B12: Fecha de emisión | C12: Denominación | D12: Tasa vigente | E12: Vencimiento | F12: Valor nominal original en circulación | G12: Valor nominal residual en circulación (1) | H12: Valor nominal actualizado en circulación (2)
C18: TÍTULOS PÚBLICOS | F18: =+F20+F44+F56 -> 1.124989e+08 | G18: =+G20+G44+G56 -> 1.1249369e+08 | H18: =+H20+H44+H56 -> 1.1252526e+08
C20: BONOS | F20: =SUM(F21:F42) -> 1.1154389e+08 | G20: =SUM(G21:G42) -> 1.1153868e+08 | H20: =SUM(H21:H42) -> 1.1153868e+08
B21: 41766 | C21: BONAR/U$S/8,75%/07-05-2024 | D21: 0.0875 | E21: 2024 | F21: 31240.452 | G21: 26035.793 | H21: 26035.793
B22: 42285 | C22: BONAR/U$S/8,00%/08-10-2020 | D22: 0.08 | E22: 2022 | F22: 7924.43 | G22: 7924.43 | H22: 7924.43
B23: 42587 | C23: BONAR/U$S/1,00%/05-08-2023 | D23: 0.01 | E23: 2023 | F23: 24998.895 | G23: 24998.895 | H23: 24998.895
B24: 42843 | C24: BONAR/U$S/5,75%/18-04-2025 | D24: 0.0575 | E24: 2025 | F24: 1960.808 | G24: 1960.808 | H24: 1960.808
B25: 42843 | C25: BONAR/U$S/7,625%/18-04-2037 | D25: 0.07625 | E25: 2037 | F25: 4021.279 | G25: 4021.279 | H25: 4021.279
B26: 44078 | C26: BONO GLOBAL/U$S/STEP UP/09-07-2030 | D26: 0.005 | E26: 2030 | F26: 16090612 | G26: 16090612 | H26: 16090612
B27: 44078 | C27: BONO GLOBAL/U$S/STEP UP/09-07-2035 | D27: 0.01125 | E27: 2035 | F27: 20501718 | G27: 20501718 | H27: 20501718
B28: 44078 | C28: BONO GLOBAL/U$S/STEP UP/09-01-2038 | D28: 0.02 | E28: 2038 | F28: 11405065 | G28: 11405065 | H28: 11405065
B29: 44078 | C29: BONO GLOBAL/U$S/STEP UP/09-07-2041 | D29: 0.025 | E29: 2041 | F29: 10482111 | G29: 10482111 | H29: 10482111
B30: 44078 | C30: BONO GLOBAL/U$S/1,00%/09-07-2029 | D30: 0.01 | E30: 2029 | F30: 2635028.7 | G30: 2635028.7 | H30: 2635028.7
B31: 44078 | C31: BONO GLOBAL/U$S/STEP UP/09-07-2046 | D31: 0.01125 | E31: 2046 | F31: 2091997.1 | G31: 2091997.1 | H31: 2091997.1
B32: 44078 | C32: BONO R.A./U$S/STEP UP/09-07-2030 | D32: 0.005 | E32: 2030 | F32: 13524104 | G32: 13524104 | H32: 13524104
... B42: 44078 | C42: BONO GLOBAL/EUR/STEP UP/09-07-2046 | D42: 0.0075 | E42: 2046 | F42: 282057.62 | G42: 282057.62 | H42: 282057.62
C44: BONOS DE LA REESTRUCTURACIÓN - DTO. 1735/04 y 563/10 | F44: =SUM(F45:F54) -> 955010.31 | G44: =SUM(G45:G54) -> 955010.31 | H44: =SUM(H45:H54) -> 972909.79
B45: 37986 | C45: PAR/U$S/TASA FIJA/31-12-2038/DTO. 1735-04/LEY ARG | D45: 0.0375 | E45: 2038 | F45: 28985.612 | G45: 28985.612 | H45: 28985.612
B46: 37986 | C46: PAR/U$S/TASA FIJA/31-12-2038/DTO. 563-10/LEY NY | D46: 0.0375 | E46: 2038 | F46: 35819.56 | G46: 35819.56 | H46: 35819.56
B47: 37986 | C47: PAR/U$S/TASA FIJA/31-12-2038/DTO. 563-10/LEY ARG | D47: 0.0375 | E47: 2038 | F47: 5563.179 | G47: 5563.179 | H47: 5563.179
B48: 37986 | C48: PAR/EUR/TASA FIJA/31-12-2038/DTO. 563-10 | D48: 0.0338 | E48: 2038 | F48: 645884.06 | G48: 645884.06 | H48: 645884.06
B49: 37986 | C49: PAR/JPY/TASA FIJA/31-12-2038/DTO. 1735-04 | D49: 0.0067 | E49: 2038 | F49: 150022.97 | G49: 150022.97 | H49: 150022.97
B50: 37986 | C50: PAR/JPY/TASA FIJA/31-12-2038/DTO. 563-10 | D50: 0.0067 | E50: 2038 | F50: 7419.9079 | G50: 7419.9079 | H50: 7419.9079
B51: 37986 | C51: DISCOUNT/USD/8,28%/31-12-2033/DTO. 1735-04/LEY ARG | D51: 0.0828 | E51: 2033 | F51: 7017.752 | G51: 7017.752 | H51: 9839.155
B52: 37986 | C52: DISCOUNT/USD/8,28%/31-12-2033/DTO. 563-10/LEY ARG | D52: 0.0828 | E52: 2033 | F52: 2855.245 | G52: 2855.245 | H52: 4003.162
B53: 37986 | C53: DISCOUNT/JPY/4,33%/31-12-2033/DTO. 1735-04 | D53: 0.0433 | E53: 2033 | F53: 49292.57 | G53: 49292.57 | H53: 58903.907
B54: 37986 | C54: DISCOUNT/JPY/4,33%/31-12-2033/DTO. 563-10 | D54: 0.0433 | E54: 2033 | F54: 22149.461 | G54: 22149.461 | H54: 26468.285
C56: AMPAROS | H56: 13664.388
C58: LETRAS DEL TESORO | F58: =SUM(F59:F74) -> 9159067.1 | G58: =SUM(G59:G74) -> 8218008.9 | H58: =SUM(H59:H74) -> 8218008.9
B59: 43630 | C59: LETES/U$S/17-01-2020 (R) | D59: Tasa Cero | E59: 2022 | F59: 5.536 | G59: 5.536 | H59: 5.536
B60: 43644 | C60: LETES/U$S/31-01-2020 (R) | D60: Tasa Cero | E60: 2022 | F60: 15.803 | G60: 15.803 | H60: 15.803
B61: 43665 | C61: LETES/U$S/14-02-2020 (R) | D61: Tasa Cero | E61: 2022 | F61: 11.736 | G61: 11.736 | H61: 11.736
B62: 43672 | C62: LETES/U$S/28-02-2020 (R) | D62: Tasa Cero | E62: 2022 | F62: 7.22 | G62: 7.22 | H62: 7.22
...

Sheet A.1.10
A1: Indice
B2: MINISTERIO DE ECONOMÍA
B3: SECRETARÍA DE FINANZAS
B6: DEUDA ELEGIBLE PENDIENTE DE REESTRUCTURACIÓN
B7: DATOS AL 31/12/2021
G10: En miles de u$s
B11: Denominación | C11: Moneda de origen | D11: Capital | E11: Atrasos de Interés (1) | F11: Intereses Compensatorios (2) | G11: Total
B17: EN MONEDA NACIONAL | D17: =SUM(D19:D31) -> 271.06328 | E17: =SUM(E19:E31) -> 25.794632 | F17: =SUM(F19:F31) -> 10.768909 | G17: =SUM(G19:G31) -> 307.62682
B19: BOCON PRE.2ºS./$/C.A./02/PRE3 | C19: Pesos | D19: 4.8625341 | E19: 0.04260279 | F19: 0.48572208 | G19: =SUM(D19:F19) -> 5.390859
B20: BOCON PRO.1ºS./$/C.A./07/PRO1 | C20: Pesos | D20: 86.884254 | E20: 5.7582359 | F20: 2.8201797 | G20: =SUM(D20:F20) -> 95.46267
B21: BOCON PRO.2ºS./$/C.A./10/PRO3 | C21: Pesos | D21: 1.3892201 | E21: 0.13964269 | F21: 0.019556726 | G21: =SUM(D21:F21) -> 1.5484196
B22: BOCON PRO.3ºS./$/C.A./07/PRO5 | C22: Pesos | D22: 58.600058 | E22: 4.4594311 | F22: 1.9622833 | G22: =SUM(D22:F22) -> 65.021773
B23: BOCON PRO.5°S./$/C.A./07/PRO9 | C23: Pesos | D23: 59.904717 | E23: 6.2588491 | F23: 1.9630773 | G23: =SUM(D23:F23) -> 68.126643
B24: EUROLETRA/$/11,75%/2007 | C24: Pesos | D24: 3.1143552 | E24: 2.0126521 | F24: 3.364585 | G24: =SUM(D24:F24) -> 8.4915923
B25: EUROLETRA/$/8,75%/2002 | C25: Pesos | D25: 0.12727981 | E25: 0.0098487307 | F25: 0.15350475 | G25: =SUM(D25:F25) -> 0.29063328
B26: Dto.1023/7-7-95/CHACO | C26: Pesos | D26: 0.024356496 | E26: 0.0044815572 | F26: 0 | G26: =SUM(D26:F26) -> 0.028838054
B27: Dto.1023/7-7-95/CHUBUT | C27: Pesos | D27: 10.528855 | E27: 0.48846365 | F27: 0 | G27: =SUM(D27:F27) -> 11.017318
B28: Dto.1023/7-7-95/RIO NEGRO | C28: Pesos | D28: 1.5010794 | E28: 0.12004487 | F28: 0 | G28: =SUM(D28:F28) -> 1.6211243
B29: Dto.1023/7-7-95/SALTA | C29: Pesos | D29: 1.9043081 | E29: 0.15229178 | F29: 0 | G29: =SUM(D29:F29) -> 2.0565999
B30: Dto.1023/7-7-95/SANT. ESTERO | C30: Pesos | D30: 0.17753353 | E30: 0.014198248 | F30: 0 | G30: =SUM(D30:F30) -> 0.19173178
B31: Dto.1023/7-7-95/M.C.B.A. | C31: Pesos | D31: 42.044728 | E31: 6.3338895 | F31: 0 | G31: =SUM(D31:F31) -> 48.378618
B33: EN MONEDA NACIONAL AJUSTABLE POR CER | D33: =SUM(D35:D58) -> 47916.291 | E33: =SUM(E35:E58) -> 1410.3157 | F33: =SUM(F35:F58) -> 6733.5622 | G33: =SUM(G35:G58) -> 56060.169
B35: LETES/U$S/15-3-2002(P) | C35: Pesos Ajustados por CER | D35: 4968.0902 | E35: 0 | F35: 0 | G35: =SUM(D35:F35) -> 4968.0902
B36: LETES/U$S/15-2-2002(P) | C36: Pesos Ajustados por CER | D36: 1840.6118 | E36: 0 | F36: 0 | G36: =SUM(D36:F36) -> 1840.6118
B37: LETES/U$S/8-3-2002(P) | C37: Pesos Ajustados por CER | D37: 1864.1487 | E37: 0 | F37: 0 | G37: =SUM(D37:F37) -> 1864.1487
B38: LETES/U$S/22-2-2002(P) | C38: Pesos Ajustados por CER | D38: 415.79685 | E38: 0 | F38: 0 | G38: =SUM(D38:F38) -> 415.79685
B39: LETES/U$S/22-3-2002(P) | C39: Pesos Ajustados por CER | D39: 454.66003 | E39: 0 | F39: 0 | G39: =SUM(D39:F39) -> 454.66003
B40: BONEX/1992(P) | C40: Pesos Ajustados por CER | D40: 3800.1623 | E40: 29.157149 | F40: 1010.4381 | G40: =SUM(D40:F40) -> 4839.7576
B41: FERROBONOS(P) | C41: Pesos Ajustados por CER | D41: 3.3838554 | E41: 0.98738341 | F41: 0 | G41: =SUM(D41:F41) -> 4.3712388
B42: PRE4(P) | C42: Pesos Ajustados por CER | D42: 1200.9179 | E42: 20.886499 | F42: 276.17618 | G42: =SUM(D42:F42) -> 1497.9806
B43: PRO2(P) | C43: Pesos Ajustados por CER | D43: 6821.9169 | E43: 364.67605 | F43: 1236.4717 | G43: =SUM(D43:F43) -> 8423.0646
B44: PRO4(P) | C44: Pesos Ajustados por CER | D44: 2500.2668 | E44: 253.26482 | F44: 265.8617 | G44: =SUM(D44:F44) -> 3019.3933
B45: PRO6(P) | C45: Pesos Ajustados por CER | D45: 4327.4731 | E45: 125.11924 | F45: 357.91176 | G45: =SUM(D45:F45) -> 4810.5041
B46: PRO8(P) | C46: Pesos Ajustados por CER | D46: 122.26251 | E46: 12.136732 | F46: 0.76074453 | G46: =SUM(D46:F46) -> 135.15999
... B58: BONO/U$S/ENC.+4.35%/2004(P) | C58: Pesos Ajustados por CER | D58: 52.65062 | E58: 2.4279456 | F58: 12.842224 | G58: =SUM(D58:F58) -> 67.920789
B60: EN MONEDA EXTRANJERA | D60: =SUM(D62:D81,D102:D176) -> 1010833.7 | E60: =SUM(E62:E81,E102:E176) -> 864247.21 | F60: =SUM(F62:F81,F102:F176) -> 507854.47 | G60: =SUM(G62:G81,G102:G176) -> 2382935.4
B62: EUROLETRA/CHF/7%/2003 | C62: CHF | D62: 8216.3999 | E62: 1150.296 | F62: 7127.0422 | G62: =SUM(D62:F62) -> 16493.738
B63: DISCOUNT/DEM/L.+0,8125%/2023 | C63: EUR | D63: 284.7937 | E63: 92.071827 | F63: 32.663935 | G63: =SUM(D63:F63) -> 409.52946
B64: PAR BONDS/DEM/5,87%/2023 | C64: EUR | D64: 3818.5605 | E64: 2913.9435 | F64: 1086.8536 | G64: =SUM(D64:F64) -> 7819.3576
B65: EUROLETRA/EUR/8,75%/2003 | C65: EUR | D65: 4262.1291 | E65: 745.8726 | F65: 4928.9748 | G65: =SUM(D65:F65) -> 9936.9765
...

Sheet A.2.1
A1: Indice
B2: MINISTERIO DE ECONOMÍA
B3: SECRETARÍA DE FINANZAS
B6: DEUDA BRUTA DE LA ADMINISTRACIÓN CENTRAL
B7: SERIE POR TRIMESTRE Y POR INSTRUMENTO
B10: En miles de u$s - TC del trimestre
B11: INSTRUMENTO | C11: 2020 | D11: 2021
C12: Saldo al 31/12/2020 | D12: Saldo al 31/03/2021 | E12: Saldo al 30/06/2021 | F12: Saldo al 30/09/2021 | G12: Saldo al 31/12/2021
B14: I- DEUDA BRUTA + VALORES NEGOCIABLES VINCULADOS AL PBI ( II+VII ) | C14: =+C17+C76 -> 3.490966e+08 | D14: =+D17+D76 -> 3.4876584e+08 | E14: =+E17+E76 -> 3.5680432e+08 | F14: =+F17+F76 -> 3.5573596e+08 | G14: =+G17+G76 -> 3.7621495e+08
B17: II- DEUDA BRUTA ( III+IV+V+VI ) | C17: =+C20+C53+C63+C68 -> 3.3558222e+08 | D17: =+D20+D53+D63+D68 -> 3.3555613e+08 | E17: =+E20+E53+E63+E68 -> 3.4352394e+08 | F17: =+F20+F53+F63+F68 -> 3.4262009e+08 | G17: =+G20+G53+G63+G68 -> 3.6323261e+08
B20: III- MEDIANO Y LARGO PLAZO | C20: =+C22+C26+C28+C51 -> 3.1036076e+08 | D20: =+D22+D26+D28+D51 -> 3.1027652e+08 | E20: =+E22+E26+E28+E51 -> 3.1794643e+08 | F20: =+F22+F26+F28+F51 -> 3.1617308e+08 | G20: =+G22+G26+G28+G51 -> 3.2576771e+08
B22: TÍTULOS PÚBLICOS | C22: =+C23+C24 -> 2.1392576e+08 | D22: =+D23+D24 -> 2.1590099e+08 | E22: =+E23+E24 -> 2.2221473e+08 | F22: =+F23+F24 -> 2.2353849e+08 | G22: =+G23+G24 -> 2.3036901e+08
B23: - Moneda nacional | C23: 47590244 | D23: 49808170 | E23: 56062277 | F23: 55630559 | G23: 60334299
B24: - Moneda extranjera | C24: 1.6633551e+08 | D24: 1.6609282e+08 | E24: 1.6615245e+08 | F24: 1.6790793e+08 | G24: 1.7003471e+08
B26: LETRAS DEL TESORO (1) | C26: 8208699.9 | D26: 8139931.6 | E26: 9653177.7 | F26: 10061943 | G26: 9432983.6
B28: PRÉSTAMOS | C28: =+C30+C32+C43+C45+C47+C49 -> 81615693 | D28: =+D30+D32+D43+D45+D47+D49 -> 80188416 | E28: =+E30+E32+E43+E45+E47+E49 -> 80267709 | F28: =+F30+F32+F43+F45+F47+F49 -> 77326285 | G28: =+G30+G32+G43+G45+G47+G49 -> 78101973
B30: PRÉSTAMOS GARANTIZADOS | C30: 605045.6 | D30: 619031.92 | E30: 670951.94 | F30: 711511.65 | G30: 751015.37
B32: ORGANISMOS INTERNACIONALES | C32: =SUM(C33:C41) -> 71268154 | D32: =SUM(D33:D41) -> 70261710 | E32: =SUM(E33:E41) -> 70563443 | F32: =SUM(F33:F41) -> 68063590 | G32: =SUM(G33:G41) -> 68065416
B33: - BCIE | C33: 2625 | D33: 2625 | E33: 6822.1454 | F33: 6822.1454 | G33: 79285.845
B34: - BIRF | C34: 7721122.2 | D34: 7738428.4 | E34: 7852691 | F34: 7805008.6 | G34: 8517393
B35: - BID | C35: 13368114 | D35: 13197692 | E35: 13144787 | F35: 13246591 | G35: 14051577
B36: - FONPLATA | C36: 323383.07 | D36: 348643.67 | E36: 352687.52 | F36: 367188.01 | G36: 404331.3
B37: - FIDA | C37: 38557.759 | D37: 38109.226 | E37: 37364.73 | F37: 36666.192 | G37: 33561.959
B38: - CAF | C38: 3649093.5 | D38: 3511722.9 | E38: 3450619.7 | F38: 3315558.1 | G38: 3781438.9
B39: - OFID | C39: 94012.406 | D39: 94406.019 | E39: 98084.263 | F39: 97479.444 | G39: 123824.5
B40: - FMI | C40: 45965303 | D40: 45229181 | E40: 45519484 | F40: 43092415 | G40: 40952110
B41: - BEI | C41: 105942.52 | D41: 100902.09 | E41: 100902.09 | F41: 95861.662 | G41: 121894.5
B43: ORGANISMOS OFICIALES | C43: 5487770.2 | D43: 5238720.6 | E43: 5053276.5 | F43: 4647416.4 | G43: 4709868.6
B45: BANCA COMERCIAL | C45: 2028569.5 | D45: 1895794 | E45: 1835199 | F45: 1818368.8 | G45: 2530002
B47: AVALES | C47: 1919958.9 | D47: 1859913.6 | E47: 1806600.4 | F47: 1726713.1 | G47: 1667070.6
... B51: ADELANTOS TRANSITORIOS BCRA | C51: 6610612.6 | D51: 6047181.6 | E51: 5810813.5 | F51: 5246366.5 | G51: 7863747
B53: IV- CORTO PLAZO | C53: =SUM(C55:C61) -> 22614317 | D53: =SUM(D55:D61) -> 22713045 | E53: =SUM(E55:E61) -> 22997850 | F53: =SUM(F55:F61) -> 23888216 | G53: =SUM(G55:G61) -> 34921032
B55: ADELANTOS TRANSITORIOS BCRA | C55: 8368887 | D55: 9123226.6 | E55: 9341176.5 | F55: 5115200.7 | G55: 13285152
B56: LETRAS DEL TESORO | C56: 10559320 | D56: 10681786 | E56: 13656673 | F56: 18773016 | G56: 20687534
B57: BILATERALES | C57: 0 | D57: 0 | E57: 0 | F57: 0 | G57: 0
B58: BANCA COMERCIAL | C58: 0 | D58: 0 | E58: 0 | F58: 0 | G58: 0
B59: PAGARÉS DEL TESORO | C59: 843781.57 | D59: 0 | E59: 0 | F59: 0 | G59: 827250.61
B60: TÍTULOS PÚBLICOS | C60: 2842328 | D60: 2908031.7 | E60: 0 | F60: 0
B61: AVALES | C61: 0 | D61: 0 | E61: 0 | F61: 0 | G61: 121095.08
B63: V- DEUDA EN SITUACIÓN DE PAGO DIFERIDO (2) | C63: =+C65+C66 -> 106676.97 | D63: =+D65+D66 -> 105311.79 | E63: =+E65+E66 -> 105782.12 | F63: =+F65+F66 -> 105086.82 | G63: =+G65+G66 -> 104561.86
...

Sheet A.2.2
A1: Indice
B2: MINISTERIO DE ECONOMÍA
B3: SECRETARÍA DE FINANZAS
B5: DEUDA BRUTA DE LA ADMINISTRACIÓN CENTRAL
B6: FLUJOS Y VARIACIONES
B7: 4to. TRIMESTRE DE 2021
C10: Miles de u$s | D10: Miles de $
B12: I - DEUDA BRUTA (EXCLUIDA LA ELEGIBLE PENDIENTE DE REESTRUCTURACIÓN), AL 30/09/2021 | C12: 3.4016639e+08 | D12: 3.3586328e+10
B14: II - DEUDA ELEGIBLE PENDIENTE DE REESTRUCTURACIÓN, AL 30/09/2021 (*) | C14: 2453700.4 | D14: 2.4226611e+08
B16: III - DEUDA BRUTA, AL 30/09/2021 (I + II) | C16: =+C12+C14 -> 3.4262009e+08 | D16: =+D12+D14 -> 3.3828594e+10
B18: VARIACIONES
B20: 1 - Financiamiento, canjes y emisiones | C20: =SUM(C22:C29) -> 31128619 | D20: =SUM(D22:D29) -> 3.0734842e+09
B22: Adelantos Transitorios del BCRA | C22: 12406948 | D22: 1225000000
B23: Letras del Tesoro - Organismos Públicos | C23: 7573997.9 | D23: 7.4781868e+08
B24: Letras Intransferibles | C24: 2242967 | D24: 2.2145934e+08
B25: Otros | C25: 526456.1 | D25: 51979643
B26: Pagarés del Tesoro | C26: 860890.26 | D26: 85000000
B27: Préstamos Organismos Multilaterales | C27: 2470105.9 | D27: 2.4388591e+08
B28: Préstamos Organismos Oficiales | C28: 102543.14 | D28: 10124597
B29: TItulos del Tesoro | C29: 4944710.4 | D29: 4.8821598e+08
B31: 2 - Amortizaciones, canjes y cancelaciones | C31: =SUM(C33:C39) -> 11540911 | D31: =SUM(D33:D39) -> 1.1394918e+09
B33: Adelantos Transitorios del BCRA | C33: 759609.05 | D33: 75000000
B34: Bonos de Consolidación | C34: 37455.821 | D34: 3698200.5
B35: Letras del Tesoro - Organismos Públicos | C35: 6004516 | D35: 5.9285588e+08
B36: Otros | C36: 26951.437 | D36: 2661050.1
B37: Préstamos Organismos Multilaterales | C37: 2271345.3 | D37: 2.2426128e+08
B38: Préstamos Organismos Oficiales | C38: 10577.341 | D38: 1044353.8
B39: TItulos del Tesoro | C39: 2430455.7 | D39: 2.3997104e+08
B41: a) Operaciones netas del período ( 1 - 2 ) | C41: =+C20-C31 -> 19587708 | D41: =+D20-D31 -> 1.9339923e+09
B43: b) Emisión Bonos de Consolidación | C43: 14164.28 | D43: 1398510.2
B45: c) Avales netos de cancelaciones | C45: 97744.213 | D45: 9650774.9
B47: d) Letras en garantía | C47: -670075.77 | D47: -66159932
B49: e) Ajustes de valuación - Excluyendo la deuda elegible pendiente de reestructuración | C49: =SUM(C51:C54) -> 1597377.7 | D49: =SUM(D51:D54) -> 1.6063022e+09
B51: Tipo de Cambio (excluye deudas ajustables por CER) | C51: -2031935.6 | D51: 9.9820972e+08
B52: Variación de la deuda ajustable por CER (efectos tipo de cambio y CER) | C52: 3271997.8 | D52: 5.7281295e+08
B53: Capitalización de Bonos del Canje, Préstamos Garantizados, Pagaré Banco Nación, Bonos de consolidación y Otros | C53: 0 | D53: 0
B54: Otras Operaciones (Registro CCF, amparos y excepciones y otros ajustes) | C54: 357315.46 | D54: 35279543
B56: f) Ajustes de valuación sobre deuda elegible pendiente de reestructuración | C56: =SUM(C58:C60) -> -14397.227 | D56: =SUM(D58:D60) -> 8372292
B58: Tipo de Cambio (excluye deudas ajustables por CER) | C58: -16896.08 | D58: 7900486.2
B59: Variación de la deuda ajustable por CER (efectos tipo de cambio y CER) | C59: 2948.788 | D59: 516230.16
...

Sheet A.2.3
A1: Indice
B2: MINISTERIO DE ECONOMÍA
B3: SECRETARÍA DE FINANZAS
B5: DEUDA BRUTA DE LA ADMINISTRACIÓN CENTRAL
B6: FLUJOS Y VARIACIONES
B7: ACUMULADO ENERO 2021 - DICIEMBRE 2021
C10: Miles de u$s | D10: Miles de $
B12: I - DEUDA BRUTA (EXCLUIDA LA ELEGIBLE PENDIENTE DE REESTRUCTURACIÓN), AL 31/12/2020 | C12: 3.3308176e+08 | D12: 2.8027164e+10
B14: II - DEUDA ELEGIBLE PENDIENTE DE REESTRUCTURACIÓN, AL 31/12/2020 (*) | C14: 2500462.6 | D14: 2.1040143e+08
B16: III - DEUDA BRUTA, AL 31/12/2020 (I + II) | C16: 3.3558222e+08 | D16: 2.8237566e+10
B18: VARIACIONES
B20: 1 - Financiamiento, canjes y emisiones | C20: =SUM(C22:C29) -> 97789473 | D20: =SUM(D22:D29) -> 9.0991923e+09
B22: Adelantos Transitorios del BCRA | C22: 24225131 | D22: 2297130000
B23: Letras del Tesoro - Organismos Públicos | C23: 37185533 | D23: 3.4542835e+09
B24: Letras Intransferibles | C24: 13763584 | D24: 1.212728e+09
B25: Otros | C25: 583603.18 | D25: 57218543
B26: Pagarés del Tesoro | C26: 860890.26 | D26: 85000000
B27: Préstamos Organismos Multilaterales | C27: 3600465.9 | D27: 3.4754346e+08
B28: Préstamos Organismos Oficiales | C28: 136979.45 | D28: 13266454
B29: TÍtulos del Tesoro | C29: 17433286 | D29: 1.6320223e+09
B31: 2 - Amortizaciones, canjes y cancelaciones | C31: =SUM(C33:C41) -> 72678259 | D31: =SUM(D33:D41) -> 6.6897569e+09
B33: Adelantos Transitorios del BCRA | C33: 14840296 | D33: 1.3845307e+09
B34: Bonos de Consolidación | C34: 141646.59 | D34: 13140812
B35: Letras del Tesoro - Organismos Públicos | C35: 25713881 | D35: 2.3734329e+09
B36: Letras Intransferibles | C36: 9625386.5 | D36: 8.0992815e+08
B37: Otros | C37: 59121.297 | D37: 5611898.1
B38: Pagarés del Tesoro | C38: 844962.76 | D38: 71108652
B39: Préstamos Organismos Multilaterales | C39: 5633512.8 | D39: 5.3846672e+08
B40: Préstamos Organismos Oficiales | C40: 612626.63 | D40: 56562824
B41: Títulos del Tesoro | C41: 15206825 | D41: 1.4369743e+09
B43: a) Operaciones netas del período ( 1 - 2 ) | C43: =+C20-C31 -> 25111214 | D43: =+D20-D31 -> 2.4094354e+09
B45: b) Emisión Bonos de Consolidación | C45: 41540.687 | D45: 3906642.8
B47: c) Avales netos de cancelaciones | C47: -2734.5085 | D47: 258197.08
B49: d) Letras en garantía | C49: -670075.77 | D49: -66159932
B51: e) Ajustes de valuación - Excluyendo la deuda elegible pendiente de reestructuración | C51: =SUM(C53:C56) -> 3231605.9 | D51: =SUM(D53:D56) -> 6.6969075e+09
B53: Tipo de Cambio (excluye deudas ajustables por CER) | C53: -8677715.8 | D53: 4.613254e+09
B54: Variación de la deuda ajustable por CER (efectos tipo de cambio y CER) | C54: 11441056 | D54: 2.0388003e+09
B55: Capitalización de Bonos del Canje, Préstamos Garantizados, Pagaré Banco Nación, Bonos de consolidación y Otros | C55: 260544.76 | D55: 23355727
B56: Otras Operaciones (Registro CCF, amparos y excepciones y otros ajustes) | C56: 207721.28 | D56: 21497481
B58: f) Ajustes de valuación sobre deuda elegible pendiente de reestructuración | C58: =SUM(C60:C62) -> -61159.459 | D58: =SUM(D60:D62) -> 40236973
...

Sheet A.2.4
A1: Indice
B2: MINISTERIO DE ECONOMÍA
B3: SECRETARÍA DE FINANZAS
B6: Serie de Tipos de Cambio y Coeficiente de Estabilización de Referencia (CER)
B9: Fecha | C9: CER | D9: Coeficiente de pesificación (1) | E9: U$S / Peso | F9: Euro (Ref) / Peso
B10: 37290 | C10: 1 | D10: 1.399959 | E10: 1.4 | F10: 1.2064
B11: 37346 | C11: 1.0481 | D11: 1.4673678 | E11: 2.9 | F11: 2.5363
B12: 37437 | C12: 1.2495 | D12: 1.7492374 | E12: 3.8 | F12: 3.7549
B13: 37529 | C13: 1.3716 | D13: 1.9202837 | E13: 3.75 | F13: 3.6942
B14: 37621 | C14: 1.4053 | D14: 1.967407 | E14: 3.4 | F14: 3.5409
B15: 37711 | C15: 1.4341 | D15: 2.00774 | E15: 2.88 | F15: 3.1359
B16: 37802 | C16: 1.4404 | D16: 2.01656 | E16: 2.8 | F16: 3.2225
B17: 37894 | C17: 1.4448 | D17: 2.02272 | E17: 2.915 | F17: 3.397
B18: 37986 | C18: 1.4568 | D18: 2.03952 | E18: 2.9175 | F18: 3.6721
B19: 38077 | C19: 1.4678 | D19: 2.05492 | E19: 2.86 | F19: 3.5174
B20: 38168 | C20: 1.4983 | D20: 2.09762 | E20: 2.958 | F20: 3.6029
B21: 38260 | C21: 1.52 | D21: 2.128 | E21: 2.981 | F21: 3.7073
... B90: 44561 | C90: 38.6418 | D90: 54.09852 | E90: 102.75 | F90: 116.80118
B92: (1) Factor de conversión de dólares a pesos aplicable cuando a las obligaciones corresponde pesificarlas a un valor de 1,40 más CER (por ejemplo, depósitos bancarios y deudas del sector público, en dólares, con legislación nacional).

Sheet A.2.5
A1: Indice
B2: MINISTERIO DE ECONOMÍA
B3: SECRETARÍA DE FINANZAS
B6: SERIE DE DEUDA DEL SECTOR PÚBLICO NACIONAL
B7: POR AÑO Y POR INSTRUMENTO
B8: AJUSTADO POR OPERACIONES CON FECHA VALOR
B10: En millones de u$s - TC de fin de cada año
B11: INSTRUMENTO | C11: Saldo
C12: 31/12/92 (*) | D12: 34334 | E12: 34699 | F12: 35064 | G12: 35430 | H12: 35795 | I12: 36160 | J12: 36525 | K12: 36891 | L12: 37256 | M12: 37621 | N12: 37986 | O12: 38352 | P12: 38717 | Q12: 39082 | R12: 39447 | S12: 39813 | T12: 40178 | U12: 40543 | V12: 40908 | W12: 41274 | X12: 41639 | Y12: 42004 | Z12: 42369 | AA12: 42735 | AB12: 43100 | AC12: 43465 | AD12: 43830 | AE12: 44196 | AF12: 44561
B14: DEUDA PÚBLICA BRUTA + VALORES NEGOCIABLES VINCULADOS AL PBI (I + V) | C14: =+C17+C50 -> 63250 | D14: =+D17+D50 -> 71112 | E14: =+E17+E50 -> 81820 | F14: =+F17+F50 -> 88711 | G14: =+G17+G50 -> 99046 | H14: =+H17+H50 -> 103718 | I14: =+I17+I50 -> 114134 | J14: =+J17+J50 -> 123366 | ... AF14: =+AF17+AF50 -> 376214.95
B17: I- TOTAL DEUDA PÚBLICA BRUTA ( II+III +IV) | C17: =+C20+C38+C40 -> 63250 | D17: =+D20+D38+D40 -> 71112 | E17: =+E20+E38+E40 -> 81820 | F17: =+F20+F38+F40 -> 88711 | G17: =+G20+G38+G40 -> 99046 | H17: =+H20+H38+H40 -> 103718 | I17: =+I20+I38+I40 -> 114134 | J17: =+J20+J38+J40 -> 123366 | ... AF17: =+AF20+AF38+AF40 -> 363232.61
B20: II- DEUDA A VENCER | C20: =+C22+C24+C36 -> 54018 | D20: =+D22+D24+D36 -> 71112 | E20: =+E22+E24+E36 -> 81820 | F20: =+F22+F24+F36 -> 88711 | G20: =+G22+G24+G36 -> 99046 | H20: =+H22+H24+H36 -> 103718 | I20: =+I22+I24+I36 -> 114134 | J20: =+J22+J24+J36 -> 123366 | ... AF20: =+AF22+AF24+AF36 -> 360688.74
B22: TÍTULOS PUBLICOS Y LETRAS DEL TESORO | C22: 17184 | D22: 48401 | E22: 57109 | F22: 59048 | G22: 69393 | H22: 74801 | I22: 82363 | J22: 91555 | K22: 98895 | L22: 83051 | M22: 91656 | N22: 96885 | O22: 92224 | P22: 75628 | Q22: 92222 | R22: 99208 | S22: 99994 | T22: 100719 | U22: 115672 | V22: 125391 | W22: 133214 | X22: 137809 | Y22: 154775 | Z22: 160150 | AA22: 208400.33 | AB22: 256515.52 | AC22: 253709.2 | AD22: 225444.52 | AE22: 235536.1 | AF22: 260489.53
B24: PRÉSTAMOS | C24: =SUM(C26:C34) -> 36834 | D24: =SUM(D26:D34) -> 22711 | E24: =SUM(E26:E34) -> 24711 | F24: =SUM(F26:F34) -> 29663 | G24: =SUM(G26:G34) -> 29653 | H24: =SUM(H26:H34) -> 28917 | I24: =SUM(I26:I34) -> 31771 | J24: =SUM(J26:J34) -> 31811 | ... AF24: =SUM(AF26:AF34) -> 79050.318
B26: PRÉSTAMOS GARANTIZADOS | C26: 0 | D26: 0 | E26: 0 | F26: 0 | G26: 0 | H26: 0 | I26: 0 | J26: 0 | K26: 0 | L26: 21284 | M26: 11636 | N26: 14124 | O26: 14646 | P26: 14269 | Q26: 13981 | R26: 13037 | S26: 11995 | T26: 4541 | U26: 4425 | V26: 4121 | W26: 3753 | X26: 3035 | Y26: 2877 | Z26: 2076 | AA26: 1844.6747 | AB26: 1139.31 | AC26: 683.54 | AD26: 640.32505 | AE26: 605.0456 | AF26: 751.01537
B28: ORGANISMOS INTERNACIONALES | C28: 7279 | D28: 10944 | E28: 11627 | F28: 14862 | G28: 16257 | H28: 16795 | I28: 19167 | J28: 20311 | K28: 21757 | L28: 32357 | M28: 31376 | N28: 32115 | O28: 30601 | P28: 25260 | Q28: 15155 | R28: 15050 | S28: 14769 | T28: 16209 | U28: 16958 | V28: 17935 | W28: 18335 | X28: 19394 | Y28: 19857 | Z28: 19768 | AA28: 20230.498 | AB28: 21326.95 | AC28: 51037.44 | AD28: 68000.788 | AE28: 71268.154 | AF28: 68065.416
B30: ORGANISMOS OFICIALES | C30: 7380 | D30: 9698 | E30: 10870 | F30: 11904 | G30: 10063 | H30: 8311 | I30: 7634 | J30: 6258 | K30: 5017 | L30: 5876 | M30: 4935 | N30: 4428 | O30: 3389 | P30: 2952 | Q30: 1606 | R30: 1907 | S30: 1275 | T30: 1749 | U30: 1479 | V30: 1410 | W30: 849 | X30: 767 | Y30: 9026 | Z30: 9183 | AA30: 7844.7182 | AB30: 8280.38 | AC30: 6912.17 | AD30: 5398.0723 | AE30: 5487.7702 | AF30: 4709.8686
B32: BANCA COMERCIAL | C32: 21736 | D32: 1564 | E32: 1702 | F32: 1908 | G32: 2280 | H32: 2366 | I32: 3585 | J32: 3655 | K32: 2168 | L32: 715 | M32: 563 | N32: 527 | O32: 396 | P32: 294 | Q32: 859 | R32: 1165 | S32: 1453 | T32: 5102 | U32: 6055 | V32: 6586 | W32: 7273 | X32: 4702 | Y32: 4221 | Z32: 3126 | AA32: 1068.5919 | AB32: 2434.14 | AC32: 1194.16 | AD32: 2784.8972 | AE32: 2028.5695 | AF32: 2530.002
B34: OTROS ACREEDORES | C34: 439 | D34: 505 | E34: 512 | F34: 989 | G34: 1053 | H34: 1445 | I34: 1385 | J34: 1587 | K34: 1913 | L34: 911 | M34: 264 | N34: 273 | O34: 242 | P34: 1436 | Q34: 1539 | R34: 2098 | S34: 2449 | T34: 2928 | U34: 1797 | V34: 1682 | W34: 1960 | X34: 2986 | Y34: 1541 | Z34: 2839 | AA34: 3431.1811 | AB34: 3101.41 | AC34: 2448.23 | AD34: 4019.7644 | AE34: 3069.9354 | AF34: 2994.0159
B36: ADELANTOS TRANSITORIOS BCRA | C36: 0 | D36: 0 | E36: 0 | F36: 0 | G36: 0 | H36: 0 | I36: 0 | J36: 0 | K36: 0 | L36: 0 | M36: 1079 | N36: 2526 | O36: 4468 | P36: 5263 | Q36: 5986 | R36: 6774 | S36: 7700 | T36: 9626 | U36: 11615 | V36: 15597 | W36: 25972 | X36: 28002 | Y36: 29402 | Z36: 25517 | AA36: 24115.153 | AB36: 25153.14 | AC36: 13296.82 | AD36: 14237.082 | AE36: 14979.5 | AF36: 21148.899
B38: III- DEUDA EN SITUACIÓN DE PAGO DIFERIDO | C38: 9232 | D38: 0 | E38: 0 | F38: 0 | G38: 0 | H38: 0 | I38: 0 | J38: 0 | K38: 0 | L38: 28 | M38: 11704.252 | N38: 28434.741 | O38: 46195.829 | P38: 5157.8648 | Q38: 6750.8946 | R38: 7271.2359 | S38: 8461.1905 | T38: 8678.4855 | U38: 9062.1741 | V38: 9265.5751 | W38: 9376.5018 | X38: 9440.1029 | Y38: 49 | Z38: 44 | AA38: 42.906828 | AB38: 107.43 | AC38: 104.84 | AD38: 103.95523 | AE38: 106.67697 | AF38: 104.56186
B40: IV- DEUDA ELEGIBLE PENDIENTE DE REESTRUCTURACIÓN | C40: 0 | D40: 0 | E40: 0 | F40: 0 | G40: 0 | H40: 0 | I40: 0 | J40: 0 | K40: 0 | L40: 0 | M40: =+M42+M44+M46 -> 5 | N40: =+N42+N44+N46 -> 41 | O40: =+O42+O44+O46 -> 132 | P40: =+P42+P44+P46 -> 24011 | Q40: =+Q42+Q44+Q46 -> 27012 | R40: =+R42+R44+R46 -> 30360 | S40: =+S42+S44+S46 -> 31036 | T40: =+T42+T44+T46 -> 32531 | ... AF40: =+AF42+AF44+AF46 -> 2439.3032
B42: CAPITAL | M42: 0 | N42: 0 | O42: 0 | P42: 17966 | Q42: 19119 | R42: 20459 | S42: 19956 | T42: 20108 | U42: 6809 | V42: 6579 | W42: 6608 | X42: 6670 | Y42: 6352 | Z42: 6101 | AA42: 3613.9822 | AB42: 1258.4 | AC42: 1218.78 | AD42: 1058.0797 | AE42: 1081.386 | AF42: 1059.021
B44: MORA DE INTERÉS | M44: 0 | N44: 0 | O44: 0 | P44: 5591 | Q44: 6958 | R44: 8398 | S44: 9028 | T44: 9700 | U44: 4409 | V44: 4599 | W44: 4874 | X44: 5168 | Y44: 5280 | Z44: 5420 | AA44: 2510.2886 | AB44: 1022.69 | AC44: 1012.57 | AD44: 863.85757 | AE44: 878.9412 | AF44: 865.68332
B46: INTERESES COMPENSATORIOS (**) | M46: 5 | N46: 41 | O46: 132 | P46: 454 | Q46: 935 | R46: 1503 | S46: 2052 | T46: 2723 | U46: 3340 | V46: 3990 | W46: 4707 | X46: 5467 | Y46: 5945 | Z46: 6441 | AA46: 2343.8065 | AB46: 595.42 | AC46: 574.07 | AD46: 513.27222 | AE46: 540.13542 | AF46: 514.5988
B50: V- VALORES NEGOCIABLES VINCULADOS AL PBI (***) | C50: 0 | D50: 0 | E50: 0 | F50: 0 | G50: 0 | H50: 0 | I50: 0 | J50: 0 | K50: 0 | L50: 0 | M50: 0 | N50: 0 | O50: 0 | P50: 28784.426 | Q50: 29052.852 | R50: 28175.633 | S50: 19871.956 | T50: 18112.885 | U50: 22730.046 | V50: 19725.328 | W50: 15942.385 | X50: 15761.738 | Y50: 14430.352 | Z50: 13324.151 | AA50: 13001.694 | AB50: 13772.18 | AC50: 13192.94 | AD50: 12962.732 | AE50: 13514.386 | AF50: 12982.343
B53: (*) Los saldos de deuda al 31/12/92 se estimaron sobre la base de ajustar los registros obrante, retrotrayendo el efecto que sobre los saldos y la composición, produjera el Plan Brady.
B54: (**) Intereses compensatorios estimados, devengados e impagos con posterioridad a la fecha de vencimiento de cada título.
B55: (***) Valor remanente total. Es la diferencia entre el máximo a pagar de 48 unidades por cada 100 de valor nocional y la suma de los montos pagados hasta la actualidad, de acuerdo con las condiciones establecidas en las respectivas normas de emisión.

Sheet A.3.1
A1: Indice
B2: MINISTERIO DE ECONOMÍA
B3: SECRETARÍA DE FINANZAS
B6: PERFIL DE VENCIMIENTOS DE CAPITAL E INTERÉS DE LA DEUDA BRUTA DE LA ADMINISTRACIÓN CENTRAL
B7: PERIODO PROYECTADO ENERO 2022 A DICIEMBRE 2022
B8: DEUDA EN SITUACIÓN DE PAGO NORMAL (1)
B10: (En miles de U$S - Tipo de cambio 31/12/2021)
C11: 2022 | O11: Total
C12: Enero | D12: Febrero | E12: Marzo | F12: Abril | G12: Mayo | H12: Junio | I12: Julio | J12: Agosto | K12: Septiembre | L12: Octubre | M12: Noviembre | N12: Diciembre
B14: TÍTULOS PÚBLICOS | C14: =+C15+C16 -> 833577.29 | D14: =+D15+D16 -> 116944.44 | E14: =+E15+E16 -> 5090056.1 | F14: =+F15+F16 -> 8595798.4 | G14: =+G15+G16 -> 4134470.4 | H14: =+H15+H16 -> 2340439.9 | I14: =+I15+I16 -> 754141.37 | J14: =+J15+J16 -> 116340.78 | ... O14: =+O15+O16 -> 31925377
B15: CAPITAL | C15: 47679.392 | D15: 11216.185 | E15: 4882425.7 | F15: 8354309.3 | G15: 3611398.8 | H15: 2091938.2 | I15: 33386.581 | J15: 11199.659 | K15: 6452338.1 | L15: 54937.645 | M15: 2706994 | N15: 8401.6925 | O15: =+SUM(C15:N15) -> 28266225
B16: INTERÉS | C16: 785897.9 | D16: 105728.25 | E16: 207630.39 | F16: 241489.12 | G16: 523071.61 | H16: 248501.66 | I16: 720754.79 | J16: 105141.12 | K16: 178961.65 | L16: 164830.26 | M16: 128849.51 | N16: 248295.7 | O16: =+SUM(C16:N16) -> 3659152
B19: LETRAS DEL TESORO | C19: =+C20+C21 -> 5145329 | D19: =+D20+D21 -> 3956744.6 | E19: =+E20+E21 -> 3907782.7 | F19: =+F20+F21 -> 2658875.1 | G19: =+G20+G21 -> 2290399 | H19: =+H20+H21 -> 2578693.8 | I19: =+I20+I21 -> 1761872.9 | J19: =+J20+J21 -> 804173.27 | ... O19: =+O20+O21 -> 23632024
B20: CAPITAL | C20: 5100709.6 | D20: 3956744.6 | E20: 3907782.7 | F20: 2634172.1 | G20: 2290399 | H20: 2578693.8 | I20: 1761872.9 | J20: 804173.27 | K20: 124646.08 | L20: 57594.19 | M20: 0 | N20: 345913.78 | O20: =+SUM(C20:N20) -> 23562702
